Workbook
Name UPDATE: 'Data Sheet'!#REF!

Sheet Data Sheet
A1: Company : Asian Paints Limited
A2: Number of shares | B2: 95.92 | C2: cr approx | E2: Book value (₹) | F2: 223
A3: Face Value | B3: ₹ 1
A4: Current Price (₹) | B4: 2640
A5: Market Capitalization | B5: =(B2*B4) -> 253228.8
A6: Dividend frequency | B6: Twice a year- Nov & Jun | D6: Dividend Yield = | F6: 0.0095
A9: PROFIT & LOSS | F9: Figures in ₹ Crores (Unless stated)
A10: Report Date | B10: 44651 | C10: 45016 | D10: 45382 | E10: 45747 | F10: 46112
A11: Sales | B11: 29101.28 | C11: 34488.59 | D11: 35494.73 | E11: 33905.62 | F11: 35583.54
A12: Raw Material Cost | B12: 17123.25 | C12: 18985.53 | D12: 17410.84 | E12: 17504.51 | F12: 17142.01
A13: Change in Inventory | B13: 1324.97 | C13: 309.73 | D13: -363.8 | E13: 205 | F13: -603.68
A14: Power and Fuel | B14: 117.23 | C14: 138.29 | D14: 133.25 | E14: 148.58 | F14: 167.1
A15: Other Mfr. Exp | B15: 2880.45 | C15: 2916.2 | D15: 2767.18 | E15: 2687.4 | F15: 2767.11
A16: Employee Cost | B16: 1794.61 | C16: 2036.41 | D16: 2334.92 | E16: 2605.78 | F16: 2809.73
A17: Selling and admin | B17: 2941.98 | C17: 3500.84 | D17: 3811.86 | E17: 3874.94 | F17: 4112.07
A18: Other Expenses | B18: 765.12 | C18: 961.21 | D18: 1087.9 | E18: 1283.2 | F18: 1282.11
A19: Other Income | B19: 295.88 | C19: 431.46 | D19: 820.96 | E19: 350.22 | F19: 727.97
A20: Depreciation | B20: 816.36 | C20: 858.02 | D20: 853 | E20: 1026.34 | F20: 1228.85
A21: Interest | B21: 95.41 | C21: 144.45 | D21: 205.17 | E21: 227.02 | F21: 195.41
... A25: Dividend Amount | B25: 1836.87 | C25: 2460.35 | D25: 3194.14 | E25: 2378.82 | F25: 2637.8
A29: BALANCE SHEET
A30: Report Date | B30: 44651 | C30: 45016 | D30: 45382 | E30: 45747 | F30: 46112
A31: Equity Capital | B31: 96 | C31: 96 | D31: 96 | E31: 96 | F31: 96
A32: Reserves | B32: 13716 | C32: 15896 | D32: 18632 | E32: 19304 | F32: 21276
A33: Borrowings | B33: 1587 | C33: 1933 | D33: 2474 | E33: 2290 | F33: 3929
A34: Long term Borrowings | B34: 45 | C34: 76 | D34: 54 | E34: 260 | F34: 1247
A35: Short term Borrowings | B35: 731 | C35: 896 | D35: 1053 | E35: 604 | F35: 1046
A36: Lease Liabilities | B36: 811 | C36: 960 | D36: 1367 | E36: 1427 | F36: 1636
A37: Other Borrowings | B37: 0 | C37: 0 | D37: 0 | E37: 0 | F37: 0
A38: Other Liabilities | B38: 7560 | C38: 7854 | D38: 8698 | E38: 8665 | F38: 9218
A39: Non controlling int | B39: 388 | C39: 454 | D39: 695 | E39: 659 | F39: 643
A40: Trade Payables | B40: 4164 | C40: 3635 | D40: 3831 | E40: 3848 | F40: 3863
A41: Advance from Customers | B41: 76 | C41: 108 | D41: 154 | E41: 174 | F41: 107
... A64: Face value | B64: 1 | C64: 1 | D64: 1 | E64: 1 | F64: 1
A71: CASH FLOW:
A72: Report Date | B72: 44651 | C72: 45016 | D72: 45382 | E72: 45747 | F72: 46112
A73: Cash from Operating Activity | B73: 986 | C73: 4193 | D73: 6104 | E73: 4424 | F73: 7088
A74: Profit from operations | B74: 4957 | C74: 6460 | D74: 7929 | E74: 6390 | F74: 7186
A75: Receivables | B75: -1326 | C75: -834 | D75: -362 | E75: 282 | F75: -274
A76: Inventory | B76: -2354 | C76: -56 | D76: 315 | E76: -805 | F76: 976
...

Sheet Financial Statement
L2: Figures in ₹ Crores (Unless stated)
C3: Actual | H3: Expected
B4: Report Date | C4: 44651 | D4: 45016 | E4: 45382 | F4: 45747 | G4: 46112 | H4: 46477 | I4: 46843 | J4: 47208 | K4: 47573 | L4: 47938
B5: Income Statement
B7: Sales | C7: ='Data Sheet'!B11 -> 29101.28 | D7: ='Data Sheet'!C11 -> 34488.59 | E7: ='Data Sheet'!D11 -> 35494.73 | F7: ='Data Sheet'!E11 -> 33905.62 | G7: ='Data Sheet'!F11 -> 35583.54 | H7: =G7*(1+H8) -> 37142.196 | I7: =H7*(1+I8) -> 38769.125 | J7: =I7*(1+J8) -> 40467.317 | K7: =J7*(1+K8) -> 42239.896 | L7: =K7*(1+L8) -> 44090.118
B8: Sales Growth % | C8: 0 | D8: =D7/C7-1 -> 0.18512278 | E8: =E7/D7-1 -> 0.029173127 | F8: =F7/E7-1 -> -0.044770308 | G8: =G7/F7-1 -> 0.049487961 | H8: =Assumptions!$D$3 -> 0.043802713 | I8: =Assumptions!$D$3 -> 0.043802713 | J8: =Assumptions!$D$3 -> 0.043802713 | K8: =Assumptions!$D$3 -> 0.043802713 | L8: =Assumptions!$D$3 -> 0.043802713
B10: COGS | C10: =SUM('Data Sheet'!B12,'Data Sheet'!B14,'Data Sheet'!B15-'Data Sheet'!B13) -> 18795.96 | D10: =SUM('Data Sheet'!C12,'Data Sheet'!C14,'Data Sheet'!C15-'Data Sheet'!C13) -> 21730.29 | E10: =SUM('Data Sheet'!D12,'Data Sheet'!D14,'Data Sheet'!D15-'Data Sheet'!D13) -> 20675.07 | F10: =SUM('Data Sheet'!E12,'Data Sheet'!E14,'Data Sheet'!E15-'Data Sheet'!E13) -> 20135.49 | G10: =SUM('Data Sheet'!F12,'Data Sheet'!F14,'Data Sheet'!F15-'Data Sheet'!F13) -> 20679.9 | H10: =H7*H11 -> 22533.941 | I10: =I7*I11 -> 23520.988 | J10: =J7*J11 -> 24551.271 | K10: =K7*K11 -> 25626.684 | L10: =L7*L11 -> 26749.202
B11: COGS % of Sales | C11: =C10/C7 -> 0.64588087 | D11: =D10/D7 -> 0.63007186 | E11: =E10/E7 -> 0.58248281 | F11: =F10/F7 -> 0.5938688 | G11: =G10/G7 -> 0.58116477 | H11: =Assumptions!$D$11 -> 0.60669382 | I11: =Assumptions!$D$11 -> 0.60669382 | J11: =Assumptions!$D$11 -> 0.60669382 | K11: =Assumptions!$D$11 -> 0.60669382 | L11: =Assumptions!$D$11 -> 0.60669382
B13: Gross Profit | C13: =C7-C10 -> 10305.32 | D13: =D7-D10 -> 12758.3 | E13: =E7-E10 -> 14819.66 | F13: =F7-F10 -> 13770.13 | G13: =G7-G10 -> 14903.64 | H13: =H7-H10 -> 14608.255 | I13: =I7-I10 -> 15248.136 | J13: =J7-J10 -> 15916.046 | ... L13: =L7-L10 -> 17340.916
B14: Gross Margin | C14: =C13/C7 -> 0.35411913 | D14: =D13/D7 -> 0.36992814 | E14: =E13/E7 -> 0.41751719 | F14: =F13/F7 -> 0.4061312 | G14: =G13/G7 -> 0.41883523 | H14: =1-H11 -> 0.39330618 | I14: =1-I11 -> 0.39330618 | J14: =1-J11 -> 0.39330618 | K14: =1-K11 -> 0.39330618 | L14: =1-L11 -> 0.39330618
B16: Operating Expenses | C16: =SUM('Data Sheet'!B16:B18) -> 5501.71 | D16: =SUM('Data Sheet'!C16:C18) -> 6498.46 | E16: =SUM('Data Sheet'!D16:D18) -> 7234.68 | F16: =SUM('Data Sheet'!E16:E18) -> 7763.92 | G16: =SUM('Data Sheet'!F16:F18) -> 8203.91 | H16: =H7*H17 -> 7731.8252 | I16: =I7*I17 -> 8070.5001 | J16: =J7*J17 -> 8424.0099 | K16: =K7*K17 -> 8793.0044 | L16: =L7*L17 -> 9178.1618
B17: OE % of Sales | C17: =C16/C7 -> 0.18905388 | D17: =D16/D7 -> 0.18842348 | E17: =E16/E7 -> 0.20382406 | F17: =F16/F7 -> 0.22898623 | G17: =G16/G7 -> 0.23055351 | H17: =Assumptions!$D$18 -> 0.20816823 | I17: =Assumptions!$D$18 -> 0.20816823 | J17: =Assumptions!$D$18 -> 0.20816823 | K17: =Assumptions!$D$18 -> 0.20816823 | L17: =Assumptions!$D$18 -> 0.20816823
B19: EBITDA | C19: =C13-C16 -> 4803.61 | D19: =D13-D16 -> 6259.84 | E19: =E13-E16 -> 7584.98 | F19: =F13-F16 -> 6006.21 | G19: =G13-G16 -> 6699.73 | H19: =H13-H16 -> 6876.4298 | I19: =I13-I16 -> 7177.6361 | J19: =J13-J16 -> 7492.036 | ... L19: =L13-L16 -> 8162.7538
B20: EBITDAMargin | C20: =C19/C7 -> 0.16506525 | D20: =D19/D7 -> 0.18150467 | E20: =E19/E7 -> 0.21369313 | F20: =F19/F7 -> 0.17714497 | G20: =G19/G7 -> 0.18828172 | H20: =H19/H7 -> 0.18513795 | I20: =I19/I7 -> 0.18513795 | J20: =J19/J7 -> 0.18513795 | ... L20: =L19/L7 -> 0.18513795
B22: Depreciation | C22: ='Data Sheet'!B20 -> 816.36 | D22: ='Data Sheet'!C20 -> 858.02 | E22: ='Data Sheet'!D20 -> 853 | F22: ='Data Sheet'!E20 -> 1026.34 | G22: ='Data Sheet'!F20 -> 1228.85 | H22: =H7*H23 -> 1053.1091 | I22: =I7*I23 -> 1099.2381 | J22: =J7*J23 -> 1147.3877 | K22: =K7*K23 -> 1197.6464 | L22: =L7*L23 -> 1250.1066
B23: Depreciation % of Sales | C23: =C22/C7 -> 0.028052374 | D23: =D22/D7 -> 0.024878373 | E23: =E22/E7 -> 0.024031737 | F23: =F22/F7 -> 0.030270498 | G23: =G22/G7 -> 0.034534226 | H23: =Assumptions!$D$22 -> 0.028353441 | I23: =Assumptions!$D$22 -> 0.028353441 | J23: =Assumptions!$D$22 -> 0.028353441 | K23: =Assumptions!$D$22 -> 0.028353441 | L23: =Assumptions!$D$22 -> 0.028353441
B25: EBIT | C25: =C19-C22 -> 3987.25 | D25: =D19-D22 -> 5401.82 | E25: =E19-E22 -> 6731.98 | F25: =F19-F22 -> 4979.87 | G25: =G19-G22 -> 5470.88 | H25: =H19-H22 -> 5823.3207 | I25: =I19-I22 -> 6078.398 | J25: =J19-J22 -> 6344.6483 | ... L25: =L19-L22 -> 6912.6473
B26: EBIT % of Sales | C26: =C25/C7 -> 0.13701287 | D26: =D25/D7 -> 0.15662629 | E26: =E25/E7 -> 0.18966139 | F26: =F25/F7 -> 0.14687447 | G26: =G25/G7 -> 0.15374749 | H26: =H25/H7 -> 0.1567845 | I26: =I25/I7 -> 0.1567845 | J26: =J25/J7 -> 0.1567845 | ... L26: =L25/L7 -> 0.1567845
B28: Interest | C28: ='Data Sheet'!B21 -> 95.41 | D28: ='Data Sheet'!C21 -> 144.45 | E28: ='Data Sheet'!D21 -> 205.17 | F28: ='Data Sheet'!E21 -> 227.02 | G28: ='Data Sheet'!F21 -> 195.41 | H28: =H7*H29 -> 188.93801 | I28: =I7*I29 -> 197.214 | J28: =J7*J29 -> 205.85251 | K28: =K7*K29 -> 214.86941 | L28: =L7*L29 -> 224.28127
B29: Interest % of Sales | C29: =C28/C7 -> 0.0032785499 | D29: =D28/D7 -> 0.0041883417 | E29: =E28/E7 -> 0.0057802947 | F29: =F28/F7 -> 0.0066956451 | G29: =G28/G7 -> 0.005491584 | H29: =Assumptions!$D$25 -> 0.0050868831 | I29: =Assumptions!$D$25 -> 0.0050868831 | J29: =Assumptions!$D$25 -> 0.0050868831 | K29: =Assumptions!$D$25 -> 0.0050868831 | L29: =Assumptions!$D$25 -> 0.0050868831
B31: EBT | C31: =C25-C28 -> 3891.84 | D31: =D25-D28 -> 5257.37 | E31: =E25-E28 -> 6526.81 | F31: =F25-F28 -> 4752.85 | G31: =G25-G28 -> 5275.47 | H31: =H25-H28 -> 5634.3827 | I31: =I25-I28 -> 5881.184 | J31: =J25-J28 -> 6138.7958 | ... L31: =L25-L28 -> 6688.366
B32: EBT % of Sales | C32: =C31/C7 -> 0.13373432 | D32: =D31/D7 -> 0.15243795 | E32: =E31/E7 -> 0.1838811 | F32: =F31/F7 -> 0.14017883 | G32: =G31/G7 -> 0.14825591 | H32: =H31/H7 -> 0.15169762 | I32: =I31/I7 -> 0.15169762 | J32: =J31/J7 -> 0.15169762 | ... L32: =L31/L7 -> 0.15169762
B34: Tax | C34: ='Data Sheet'!B23 -> 1102.91 | D34: ='Data Sheet'!C23 -> 1493.5 | E34: ='Data Sheet'!D23 -> 1790.08 | F34: ='Data Sheet'!E23 -> 1393.36 | G34: ='Data Sheet'!F23 -> 1608.75 | H34: =H31*H35 -> 1622.5283 | I34: =I31*I35 -> 1693.5994 | J34: =J31*J35 -> 1767.7837 | K34: =K31*K35 -> 1845.2174 | L34: =L31*L35 -> 1926.0429
B35: Effective Tax Rates | C35: =C34/C31 -> 0.28339038 | D35: =D34/D31 -> 0.2840774 | E35: =E34/E31 -> 0.27426568 | F35: =F34/F31 -> 0.29316305 | G35: =G34/G31 -> 0.30494913 | H35: =Assumptions!$D$28 -> 0.28796913 | I35: =Assumptions!$D$28 -> 0.28796913 | J35: =Assumptions!$D$28 -> 0.28796913 | K35: =Assumptions!$D$28 -> 0.28796913 | L35: =Assumptions!$D$28 -> 0.28796913
B37: Net Profit | C37: =C31-C34 -> 2788.93 | D37: =D31-D34 -> 3763.87 | E37: =E31-E34 -> 4736.73 | F37: =F31-F34 -> 3359.49 | G37: =G31-G34 -> 3666.72 | H37: =H31-H34 -> 4011.8544 | I37: =I31-I34 -> 4187.5846 | J37: =J31-J34 -> 4371.0121 | ... L37: =L31-L34 -> 4762.3231
B38: Net Margin | C38: =C37/C7 -> 0.095835303 | D38: =D37/D7 -> 0.10913377 | E38: =E37/E7 -> 0.13344882 | F38: =F37/F7 -> 0.099083574 | G38: =G37/G7 -> 0.1030454 | H38: =H37/H7 -> 0.10801339 | I38: =I37/I7 -> 0.10801339 | J38: =J37/J7 -> 0.10801339 | ... L38: =L37/L7 -> 0.10801339
B41: Numbers of Shares | C41: ='Data Sheet'!$B$2 -> 95.92 | D41: ='Data Sheet'!$B$2 -> 95.92 | E41: ='Data Sheet'!$B$2 -> 95.92 | F41: ='Data Sheet'!$B$2 -> 95.92 | G41: ='Data Sheet'!$B$2 -> 95.92 | H41: ='Data Sheet'!$B$2 -> 95.92 | I41: ='Data Sheet'!$B$2 -> 95.92 | J41: ='Data Sheet'!$B$2 -> 95.92 | ... L41: ='Data Sheet'!$B$2 -> 95.92
B43: EPS | C43: =C37/C41 -> 29.075584 | D43: =D37/D41 -> 39.239679 | E43: =E37/E41 -> 49.382089 | F43: =F37/F41 -> 35.023874 | G43: =G37/G41 -> 38.226856 | H43: =H37/H41 -> 41.825005 | I43: =I37/I41 -> 43.657053 | J43: =J37/J41 -> 45.569351 | ... L43: =L37/L41 -> 49.648906
B47: BALANCE SHEET | L47: Figures in ₹ Crores (Unless stated)
B48: Report Date | C48: 44651 | D48: 45016 | E48: 45382 | F48: 45747 | G48: 46112 | H48: 46477 | I48: 46843 | J48: 47208 | K48: 47573 | L48: 47938
B50: Equity Capital | C50: 96 | D50: 96 | E50: 96 | F50: 96 | G50: 96
B51: Reserves | C51: 13716 | D51: 15896 | E51: 18632 | F51: 19304 | G51: 21276
A52: # | B52: Borrowings | C52: 1587 | D52: 1933 | E52: 2474 | F52: 2290 | G52: 3929
B53: Long term Borrowings | C53: 45 | D53: 76 | E53: 54 | F53: 260 | G53: 1247
A54: # | B54: Short term Borrowings | C54: 731 | D54: 896 | E54: 1053 | F54: 604 | G54: 1046
B55: Lease Liabilities | C55: 811 | D55: 960 | E55: 1367 | F55: 1427 | G55: 1636
B56: Other Borrowings | C56: 0 | D56: 0 | E56: 0 | F56: 0 | G56: 0
B57: Other Liabilities | C57: 7560 | D57: 7854 | E57: 8698 | F57: 8665 | G57: 9218
B58: Non controlling int | C58: 388 | D58: 454 | E58: 695 | F58: 659 | G58: 643
B59: Trade Payables | C59: 4164 | D59: 3635 | E59: 3831 | F59: 3848 | G59: 3863
...

Sheet Assumptions
A2: 1 | B2: Sales Assumption Type | D2: Rate
B3: Base Case | D3: =IF(B3=B6,C6,IF(B3=B7,C7,IF(B3=B8,C8))) -> 0.043802713
B5: Sales
B6: Bull Case | C6: =C8+20%*C8 -> 0.052563255
B7: Bear Case | C7: =C8-20%*C8 -> 0.03504217
B8: Base Case | C8: =AVERAGE('Financial Statement'!C8:G8) -> 0.043802713
A10: 2 | B10: Sales Assumption Type | D10: Rate
B11: Base Case | D11: =IF(B11=B13,C13,IF(B11=B14,C14,IF(B11=B15,C15))) -> 0.60669382
B12: COGS
B13: Bull Case | C13: =C15+20%*C15 -> 0.72803259
B14: Bear Case | C14: =C15-20%*C15 -> 0.48535506
B15: Base Case | C15: =AVERAGE('Financial Statement'!C11:G11) -> 0.60669382
A17: 3 | B17: Operating Expenses | D17: Rate
B18: Avg of OpEx % of Sales | D18: =AVERAGE('Financial Statement'!C17:G17) -> 0.20816823
A21: 4 | B21: Depreciation | D21: Rate
B22: Average of Dep % | D22: =AVERAGE('Financial Statement'!C23:G23) -> 0.028353441
A24: 4 | B24: Interest | D24: Rate
B25: Interest % average | D25: =AVERAGE('Financial Statement'!C29:G29) -> 0.0050868831
A27: 5 | B27: Tax | D27: Rate
B28: Average | D28: =AVERAGE('Financial Statement'!C35:G35) -> 0.28796913
A30: Calculating Capital expenditure | G30: Figures in ₹ Crores (Unless stated)
A31: Year | B31: 44286 | C31: 44651 | D31: 45016 | E31: 45382 | F31: 45747
A32: Historical Capex | B32: =-'Data Sheet'!B81 -> 551 | C32: =-'Data Sheet'!C81 -> 1446 | D32: =-'Data Sheet'!D81 -> 2496 | E32: =-'Data Sheet'!E81 -> 1830 | F32: =-'Data Sheet'!F81 -> 1487
A34: Capex % of Revenue | B34: =B32/'Financial Statement'!C7 -> 0.018933875 | C34: =C32/'Financial Statement'!D7 -> 0.04192691 | D34: =D32/'Financial Statement'!E7 -> 0.070320298 | E34: =E32/'Financial Statement'!F7 -> 0.053973353 | F34: =F32/'Financial Statement'!G7 -> 0.041788984
A36: Forecast Capex % | B36: =AVERAGE($B$34:$G$34) -> 0.045388684
A38: Year | B38: 46477 | C38: 46843 | D38: 47208 | E38: 47573 | F38: 47938
A39: Forecast Capex | B39: =$B$36*'Financial Statement'!H7 -> 1685.8354 | C39: =$B$36*'Financial Statement'!I7 -> 1759.6795 | D39: =$B$36*'Financial Statement'!J7 -> 1836.7583 | E39: =$B$36*'Financial Statement'!K7 -> 1917.2133 | F39: =$B$36*'Financial Statement'!L7 -> 2001.1924
A42: Calculating Net Working Capital | G42: Figures in ₹ Crores (Unless stated)
A43: Year | B43: 44286 | C43: 44651 | D43: 45016 | E43: 45382 | F43: 45747
A44: Inventory | B44: ='Data Sheet'!B58 -> 6153 | C44: ='Data Sheet'!C58 -> 6211 | D44: ='Data Sheet'!D58 -> 5923 | E44: ='Data Sheet'!E58 -> 6719 | F44: ='Data Sheet'!F58 -> 5744
A46: Trade Receiveable | B46: ='Data Sheet'!B59 -> 3871 | C46: ='Data Sheet'!C59 -> 4637 | D46: ='Data Sheet'!D59 -> 4889 | E46: ='Data Sheet'!E59 -> 4314 | F46: ='Data Sheet'!F59 -> 4462
A48: Trade Payable | B48: ='Data Sheet'!B40 -> 4164 | C48: ='Data Sheet'!C40 -> 3635 | D48: ='Data Sheet'!D40 -> 3831 | E48: ='Data Sheet'!E40 -> 3848 | F48: ='Data Sheet'!F40 -> 3863
A50: Net Working Capital | B50: =SUM(B44,B46)-B48 -> 5860 | C50: =SUM(C44,C46)-C48 -> 7213 | D50: =SUM(D44,D46)-D48 -> 6981 | E50: =SUM(E44,E46)-E48 -> 7185 | F50: =SUM(F44,F46)-F48 -> 6343
A52: Change in WC | B52: NA | C52: =C50-B50 -> 1353 | D52: =D50-C50 -> -232 | E52: =E50-D50 -> 204 | F52: =F50-E50 -> -842
A54: NWC % of Sales | B54: =B50/'Financial Statement'!C7 -> 0.20136571 | C54: =C50/'Financial Statement'!D7 -> 0.20914163 | D54: =D50/'Financial Statement'!E7 -> 0.19667708 | E54: =E50/'Financial Statement'!F7 -> 0.21191177 | F54: =F50/'Financial Statement'!G7 -> 0.17825658
A56: Forecast NWC % | B56: =AVERAGE(B54:G54) -> 0.19947056
A57: Year | B57: 46477 | C57: 46843 | D57: 47208 | E57: 47573 | F57: 47938
A58: Forecast NWC | B58: =$B$56*'Financial Statement'!H7 -> 7408.7744 | C58: =$B$56*'Financial Statement'!I7 -> 7733.2988 | D58: =$B$56*'Financial Statement'!J7 -> 8072.0383 | E58: =$B$56*'Financial Statement'!K7 -> 8425.6154 | F58: =$B$56*'Financial Statement'!L7 -> 8794.6803
A60: Change if Forecaster NWC | B60: =B58-F50 -> 1065.7744 | C60: =C58-B58 -> 324.52442 | D60: =D58-C58 -> 338.73947 | E60: =E58-D58 -> 353.57717 | F60: =F58-E58 -> 369.06481
A62: Cost of Equity
...

Sheet FCFF
F1: Figures in ₹ Crores (Unless stated)
A2: Item | B2: 46477 | C2: 46843 | D2: 47208 | E2: 47573 | F2: 47938
A3: FCFF Schedule
A4: EBIT | B4: ='Financial Statement'!H25 -> 5823.3207 | C4: ='Financial Statement'!I25 -> 6078.398 | D4: ='Financial Statement'!J25 -> 6344.6483 | E4: ='Financial Statement'!K25 -> 6622.5611 | F4: ='Financial Statement'!L25 -> 6912.6473
A5: Tax Rate | B5: ='Financial Statement'!H35 -> 0.28796913 | C5: ='Financial Statement'!I35 -> 0.28796913 | D5: ='Financial Statement'!J35 -> 0.28796913 | E5: ='Financial Statement'!K35 -> 0.28796913 | F5: ='Financial Statement'!L35 -> 0.28796913
A6: NOPAT | B6: =B4*(1-B5) -> 4146.3841 | C6: =C4*(1-C5) -> 4328.007 | D6: =D4*(1-D5) -> 4517.5855 | E6: =E4*(1-E5) -> 4715.468 | F6: =F4*(1-F5) -> 4922.0183
A7: Depreciation & Amortization | B7: ='Financial Statement'!H22 -> 1053.1091 | C7: ='Financial Statement'!I22 -> 1099.2381 | D7: ='Financial Statement'!J22 -> 1147.3877 | E7: ='Financial Statement'!K22 -> 1197.6464 | F7: ='Financial Statement'!L22 -> 1250.1066
A8: Capital Expenditure (Capex) | B8: =Assumptions!B39 -> 1685.8354 | C8: =Assumptions!C39 -> 1759.6795 | D8: =Assumptions!D39 -> 1836.7583 | E8: =Assumptions!E39 -> 1917.2133 | F8: =Assumptions!F39 -> 2001.1924
A9: Change in Net Working Capital | B9: =Assumptions!B60 -> 1065.7744 | C9: =Assumptions!C60 -> 324.52442 | D9: =Assumptions!D60 -> 338.73947 | E9: =Assumptions!E60 -> 353.57717 | F9: =Assumptions!F60 -> 369.06481
A10: FCFF | B10: =SUM(B6,B7)-(B8)-(B9) -> 2447.8834 | C10: =SUM(C6,C7)-(C8)-(C9) -> 3343.0412 | D10: =SUM(D6,D7)-(D8)-(D9) -> 3489.4754 | E10: =SUM(E6,E7)-(E8)-(E9) -> 3642.3239 | F10: =SUM(F6,F7)-(F8)-(F9) -> 3801.8676
A12: Present Value of FCFF | B12: =B10/(1+$B$39)^1 -> 2253.1816 | C12: =C10/(1+$B$39)^2 -> 2832.3873 | D12: =D10/(1+$B$39)^3 -> 2721.3006 | E12: =E10/(1+$B$39)^4 -> 2614.5707 | F12: =F10/(1+$B$39)^5 -> 2512.0268
A14: Present Value of forecasted FCFF | B14: =SUM(B12:F12) -> 12933.467 | C14: PV=(FCFF)/(1+WACC)n
A16: FCFF2031 | B16: =F10*(1+Assumptions!B78) -> 3934.933 | C16: FCFFn​ = FCFF in our final forecast year, Mar-31
A18: =A45 -> Terminal Value | B18: =B16/(B39-Assumptions!B78) -> 76537.289 | C18: FCFFn+1​ = FCFF in the following year, Mar-32
A19: Present Value of Terminal Value | B19: =B18/(1+$B$39)^5 -> 50570.863 | C19: WACC = | D19: =B39 -> 0.086411972
C20: g = perpetual growth rate | F20: =Assumptions!B78 -> 0.035
A22: Enterprise Value | B22: =B14+B19 -> 63504.33
A24: Equity Value | B24: =B22-'Financial Statement'!G52+'Financial Statement'!G79+'Financial Statement'!G75 -> 67711.33
A26: Equity value per share | B26: =B24/'Data Sheet'!B2 -> 705.91461
A30: Market Value and Share of Equity and Debt
A31: Market Value of Equity | B31: =Valuation!C8*Valuation!C6 -> 253228.8
A32: Market Value of Debt | B32: ='Financial Statement'!G52 -> 3929
A33: Total Capital | B33: =SUM(B31:B32) -> 257157.8
A35: Equity Weight | B35: =B31/B33 -> 0.98472144
A37: Debt Weight | B37: =B32/B33 -> 0.015278557
A39: WACC | B39: =(B35*Assumptions!B66)+(FCFF!B37*Assumptions!B73*(1-'Financial Statement'!G35)) -> 0.086411972 | C39: E/V = Equity Weight
C40: Ke = Cost of Equity
C41: D/V = Debt Weight
C42: Kd = Pre-tax Cost of Debt
C43: T = Tax Rate
A45: Terminal Value | B45: "=FCFF2032/WACC-g" | C45: FCFF 2032 = Mar-31 FCFF grown one more year
A46: Terminal growth should represent long-term sustainable growth, not the company's temporary high-growth period.For a mature company, we'd normally want a conservative long-term rate, generally below the economy's long-term nominal growth and, most importantly: g<WACC | C46: WACC =8.65%
C47: g = perpetual growth rate

Sheet Valuation
D1: Figures in ₹ Crores (Unless stated)
B2: Select the FY for EPS Forward
B3: 46477 | C3: =INDEX('Financial Statement'!H43:L43, MATCH(B3,'Financial Statement'!H4:L4,0)) -> 41.825005
B4: Target P/E | C4: 50 | D4: (As per historical data and Yahoo finance)
B5: Target Price | C5: =C3*C4 -> 2091.2502
B6: Current Price | C6: ='Data Sheet'!$B$4 -> 2640
B8: Number of shares = | C8: ='Data Sheet'!B2 -> 95.92 | D8: cr (approx)
B9: Dividend Yield % | C9: ='Data Sheet'!F6 -> 0.0095
B11: Price Return % | C11: =(C5/C6)-1 -> -0.20785976
B13: Total Expected Return | C13: =C11+C9 -> -0.19835976
B15: Recommendation | C15: =IF(C13>0.1,"BUY",IF(C13<-0.1,"SELL","HOLD")) -> SELL
B16: Recommendation is based on total return approach (including dividends)

Sheet Report
B2: Report Date | C2: 46477 | D2: 46843 | E2: 47208 | F2: 47573 | G2: 47938
B3: Revenue | C3: ='Financial Statement'!H7 -> 37142.196 | D3: ='Financial Statement'!I7 -> 38769.125 | E3: ='Financial Statement'!J7 -> 40467.317 | F3: ='Financial Statement'!K7 -> 42239.896 | G3: ='Financial Statement'!L7 -> 44090.118
B4: EBITDA | C4: ='Financial Statement'!H19 -> 6876.4298 | D4: ='Financial Statement'!I19 -> 7177.6361 | E4: ='Financial Statement'!J19 -> 7492.036 | F4: ='Financial Statement'!K19 -> 7820.2075 | G4: ='Financial Statement'!L19 -> 8162.7538
B5: Net Profit | C5: ='Financial Statement'!H37 -> 4011.8544 | D5: ='Financial Statement'!I37 -> 4187.5846 | E5: ='Financial Statement'!J37 -> 4371.0121 | F5: ='Financial Statement'!K37 -> 4562.4743 | G5: ='Financial Statement'!L37 -> 4762.3231
B7: FCFF | C7: =FCFF!B10 -> 2447.8834 | D7: =FCFF!C10 -> 3343.0412 | E7: =FCFF!D10 -> 3489.4754 | F7: =FCFF!E10 -> 3642.3239 | G7: =FCFF!F10 -> 3801.8676
B8: WACC | C8: =FCFF!B39 -> 0.086411972
B9: Present Value of FCFF | C9: =FCFF!B12 -> 2253.1816 | D9: =FCFF!C12 -> 2832.3873 | E9: =FCFF!D12 -> 2721.3006 | F9: =FCFF!E12 -> 2614.5707 | G9: =FCFF!F12 -> 2512.0268
B11: Terminal Value | C11: =FCFF!B18 -> 76537.289
B13: Present Value of TV | C13: =FCFF!B19 -> 50570.863
B15: Enterprise Value | C15: =FCFF!B22 -> 63504.33
B17: Equity Value | C17: =FCFF!B24 -> 67711.33
B19: Equity Value Per Share | C19: =FCFF!B26 -> 705.91461
