Workbook
Name UPDATE: 'Data Sheet'!$E$1

Sheet Data Sheet
A1: COMPANY NAME | B1: ICICI BANK LTD
A2: Number of shares | B2: =IF(B5>0, B5/B4, 0) -> 717.56021
A3: Face Value | B3: 2
A4: Current Price | B4: 1435.4
A5: Market Capitalization | B5: 1029985.9
A11: PROFIT & LOSS | G11: Value in Crore unless stated
A12: Report Date | B12: 44286 | C12: 44651 | D12: 45016 | E12: 45382 | F12: 45747 | G12: 46112
A13: Sales | B13: 89162.66 | C13: 95406.87 | D13: 121066.81 | E13: 159515.93 | F13: 186331.46 | G13: 195218.46
A14: Other Mfr. Exp | B14: 2178.52 | C14: 2699.47 | D14: 3464.42 | E14: 3617.18 | F14: 3820.07 | G14: 4694.76
A15: Employee Cost | B15: 11063.46 | C15: 12353.95 | D15: 15247.91 | E15: 19186.58 | F15: 23650.86 | G15: 25279.14
A16: Selling and admin | B16: 6402.88 | C16: 6167.72 | D16: 7565.2 | E16: 7643.68 | F16: 8207.53 | G16: 8160.59
A17: Other Expenses | B17: 71664.11 | C17: 59577.23 | D17: 61586.85 | E17: 69112.55 | F17: 94399.96 | G17: 104836.97
A18: Other Income | B18: 72173.81 | C18: 62129.45 | D18: 65111.99 | E18: 76521.8 | F18: 108255.47 | G18: 116899.9
A19: Depreciation | B19: 1340.07 | C19: 1330.01 | D19: 1514.56 | E19: 1935.21 | F19: 2627.32 | G19: 3061
A20: Interest | B20: 42659.09 | C20: 41166.67 | D20: 50543.39 | E20: 74108.16 | F20: 89027.65 | G20: 89028.58
A21: Profit before tax | B21: 26028.34 | C21: 34241.27 | D21: 46256.47 | E21: 60434.37 | F21: 72853.54 | G21: 77057.32
A22: Tax | B22: 5664.37 | C22: 8457.44 | D22: 11793.44 | E22: 15427.62 | F22: 18434.83 | G22: 19383.93
A23: Net profit | B23: 18384.32 | C23: 25110.1 | D23: 34036.64 | E23: 44256.37 | F23: 51029.2 | G23: 54207.7
A24: Dividend Amount | B24: 1383.41 | C24: 3474.92 | D24: 5587.12 | E24: 7023.4 | F24: 7835.3 | G24: 8593.38
A25: Divided Payout ratio | B25: =B24/B23 -> 0.075249452 | C25: =C24/C23 -> 0.13838734 | D25: =D24/D23 -> 0.16415016 | E25: =E24/E23 -> 0.15869806 | F25: =F24/F23 -> 0.15354542 | G25: =G24/G23 -> 0.15852693
A27: Cash Flow
A28: Report Date | B28: 44286 | C28: 44651 | D28: 45016 | E28: 45382 | F28: 45747 | G28: 46112
A29: Cash from Operating Activity | B29: 138015 | C29: 58111 | D29: -3771 | E29: 157284 | F29: 122805 | G29: 67325
A30: Profit from operations | B30: 39859 | C30: 45576 | D30: 56183 | E30: 66993 | F30: 76904 | G30: 83930
A31: Loans Advances | B31: -96893 | C31: -134905 | D31: -163893 | E31: -178265 | F31: -164020 | G31: -230271
A32: Operating investments | B32: 9048 | C32: -16669 | D32: -15829 | E32: 16736 | F32: 7501 | G32: 6075
A33: Operating Deposits | B33: 159156 | C33: 131426 | D33: 119466 | E33: 232993 | F33: 198057 | G33: 188380
A34: Other WC items | B34: 30680 | C34: 37665 | D34: 11177 | E34: 32171 | F34: 22479 | G34: 35760
A35: Working capital changes | B35: 101990 | C35: 17517 | D35: -49078 | E35: 103635 | F35: 64018 | G35: -56
A36: Direct taxes | B36: -3834 | C36: -4982 | D36: -10875 | E36: -13344 | F36: -18116 | G36: -16548
A37: Cash from Investing Activity | B37: -63631 | C37: -40007 | D37: -67689 | E37: -144737 | F37: -77140 | G37: -11708
A38: Fixed assets purchased | B38: -1688 | C38: -1860 | D38: -2468 | E38: -3679 | F38: -4770 | G38: -3730
A39: Fixed assets sold | B39: 12 | C39: 117 | D39: 287 | E39: 70 | F39: 65 | G39: 183
... A48: Free Cash Flow | B48: 136339 | C48: 56369 | D48: -5951 | E48: 153676 | F48: 118100 | G48: 63778
A49: CFO/OP | B49: =B29/B30 -> 3.4625806 | C49: =C29/C30 -> 1.2750351 | D49: =D29/D30 -> -0.067119947 | E49: =E29/E30 -> 2.3477677 | F49: =F29/F30 -> 1.596861 | G49: =G29/G30 -> 0.80215656
A51: Balance sheet
A52: Report Date | B52: Mar-21 | C52: Mar-22 | D52: Mar-23 | E52: Mar-24 | F52: Mar-25 | G52: Mar-26
A53: Balance sheet
A54: Equity Capital | B54: 1383 | C54: 1390 | D54: 1397 | E54: 1405 | F54: 1425 | G54: 1432
A55: Reserves | B55: 156204 | C55: 180663 | D55: 213101 | E55: 254739 | F55: 312481 | G55: 361628
...

Sheet Financial Statement
B3: EQUITY RESEARCH ON ICICI BANK
C6: Actual | H6: Expected
B7: Report Date | C7: Mar-21 | D7: Mar-22 | E7: Mar-23 | F7: Mar-24 | G7: Mar-25 | H7: Mar-26 | I7: Mar-27 | J7: Mar-28 | K7: Mar-29 | L7: Mar-30
B8: Consolidated P/L Acc
B10: Total Operating Income | C10: =SUM('Data Sheet'!B13+'Data Sheet'!B18) -> 161336.47 | D10: =SUM('Data Sheet'!C13+'Data Sheet'!C18) -> 157536.32 | E10: =SUM('Data Sheet'!D13+'Data Sheet'!D18) -> 186178.8 | F10: =SUM('Data Sheet'!E13+'Data Sheet'!E18) -> 236037.73 | G10: =SUM('Data Sheet'!F13+'Data Sheet'!F18) -> 294586.93 | H10: =G10*(1+H11) -> 344233.11 | I10: =H10*(1+I11) -> 402246.06 | J10: =I10*(1+J11) -> 470035.82 | K10: =J10*(1+K11) -> 549250.06 | L10: =K10*(1+L11) -> 641814.13
B11: Income Growth Rate | D11: =D10/C10-1 -> -0.023554191 | E11: =E10/D10-1 -> 0.18181509 | F11: =F10/E10-1 -> 0.26780133 | G11: =G10/F10-1 -> 0.24805017 | H11: =Assumption!$G$4 -> 0.1685281 | I11: =Assumption!$G$4 -> 0.1685281 | J11: =Assumption!$G$4 -> 0.1685281 | K11: =Assumption!$G$4 -> 0.1685281 | L11: =Assumption!$G$4 -> 0.1685281
B13: Operating Expenses | C13: =SUM('Data Sheet'!B14:B17) -> 91308.97 | D13: =SUM('Data Sheet'!C14:C17) -> 80798.37 | E13: =SUM('Data Sheet'!D14:D17) -> 87864.38 | F13: =SUM('Data Sheet'!E14:E17) -> 99559.99 | G13: =SUM('Data Sheet'!F14:F17) -> 130078.42 | H13: =H10*H14 -> 166205.07 | I13: =I10*I14 -> 194215.29 | J13: =J10*J14 -> 226946.03 | K13: =K10*K14 -> 265192.81 | L13: =L10*L14 -> 309885.25
B14: Cost to Income ratio | C14: =C13/C10 -> 0.56595369 | D14: =D13/D10 -> 0.51288725 | E14: =E13/E10 -> 0.47193547 | F14: =F13/F10 -> 0.42179693 | G14: =G13/G10 -> 0.44156209 | H14: =Assumption!$G$9 -> 0.48282709 | I14: =Assumption!$G$9 -> 0.48282709 | J14: =Assumption!$G$9 -> 0.48282709 | K14: =Assumption!$G$9 -> 0.48282709 | L14: =Assumption!$G$9 -> 0.48282709
B16: Operating Profit | C16: =C10-C13 -> 70027.5 | D16: =D10-D13 -> 76737.95 | E16: =E10-E13 -> 98314.42 | F16: =F10-F13 -> 136477.74 | G16: =G10-G13 -> 164508.51 | H16: =H10-H13 -> 178028.04 | I16: =I10-I13 -> 208030.77 | J16: =J10-J13 -> 243089.8 | ... L16: =L10-L13 -> 331928.89
B17: Operating Margin | C17: =C16/C10 -> 0.43404631 | D17: =D16/D10 -> 0.48711275 | E17: =E16/E10 -> 0.52806453 | F17: =F16/F10 -> 0.57820307 | G17: =G16/G10 -> 0.55843791 | H17: =H16/H10 -> 0.51717291 | I17: =I16/I10 -> 0.51717291 | J17: =J16/J10 -> 0.51717291 | ... L17: =L16/L10 -> 0.51717291
B19: Interest | C19: ='Data Sheet'!B20 -> 42659.09 | D19: ='Data Sheet'!C20 -> 41166.67 | E19: ='Data Sheet'!D20 -> 50543.39 | F19: ='Data Sheet'!E20 -> 74108.16 | G19: ='Data Sheet'!F20 -> 89027.65 | H19: =H10*H20 -> 97306.648 | I19: =I10*I20 -> 113705.55 | J19: =J10*J20 -> 132868.13 | K19: =K10*K20 -> 155260.15 | L19: =L10*L20 -> 181425.85
B20: Interest Rate | C20: =C19/C10 -> 0.26441071 | D20: =D19/D10 -> 0.26131542 | E20: =E19/E10 -> 0.27147769 | F20: =F19/F10 -> 0.31396743 | G20: =G19/G10 -> 0.30221181 | H20: =Assumption!$G$11 -> 0.28267661 | I20: =Assumption!$G$11 -> 0.28267661 | J20: =Assumption!$G$11 -> 0.28267661 | K20: =Assumption!$G$11 -> 0.28267661 | L20: =Assumption!$G$11 -> 0.28267661
B22: Depreciation | C22: ='Data Sheet'!B19 -> 1340.07 | D22: ='Data Sheet'!C19 -> 1330.01 | E22: ='Data Sheet'!D19 -> 1514.56 | F22: ='Data Sheet'!E19 -> 1935.21 | G22: ='Data Sheet'!F19 -> 2627.32 | H22: =H10*H23 -> 2891.6258 | I22: =I10*I23 -> 3378.946 | J22: =J10*J23 -> 3948.3934 | K22: =K10*K23 -> 4613.8086 | L22: =L10*L23 -> 5391.365
B23: Dep rate % of Revenue | C23: =C22/C10 -> 0.0083060575 | D23: =D22/D10 -> 0.0084425611 | E23: =E22/E10 -> 0.0081349756 | F23: =F22/F10 -> 0.0081987316 | G23: =G22/G10 -> 0.0089186577 | H23: =Assumption!$G$15 -> 0.0084001967 | I23: =Assumption!$G$15 -> 0.0084001967 | J23: =Assumption!$G$15 -> 0.0084001967 | K23: =Assumption!$G$15 -> 0.0084001967 | L23: =Assumption!$G$15 -> 0.0084001967
B25: Profit Before Tax | C25: =C16-(C19+C22) -> 26028.34 | D25: =D16-(D19+D22) -> 34241.27 | E25: =E16-(E19+E22) -> 46256.47 | F25: =F16-(F19+F22) -> 60434.37 | G25: =G16-(G19+G22) -> 72853.54 | H25: =H16-(H19+H22) -> 77829.765 | I25: =I16-(I19+I22) -> 90946.267 | J25: =J16-(J19+J22) -> 106273.27 | ... L25: =L16-(L19+L22) -> 145111.68
B26: PBT % | C26: =C25/C10 -> 0.16132955 | D26: =D25/D10 -> 0.21735477 | E26: =E25/E10 -> 0.24845186 | F26: =F25/F10 -> 0.25603691 | G26: =G25/G10 -> 0.24730744 | H26: =H25/H10 -> 0.22609611 | I26: =I25/I10 -> 0.22609611 | J26: =J25/J10 -> 0.22609611 | ... L26: =L25/L10 -> 0.22609611
B28: Tax | C28: ='Data Sheet'!B22 -> 5664.37 | D28: ='Data Sheet'!C22 -> 8457.44 | E28: ='Data Sheet'!D22 -> 11793.44 | F28: ='Data Sheet'!E22 -> 15427.62 | G28: ='Data Sheet'!F22 -> 18434.83 | H28: =H25*H29 -> 19113.353 | I28: =I25*I29 -> 22334.49 | J28: =J25*J29 -> 26098.479 | K28: =K25*K29 -> 30496.806 | L28: =L25*L29 -> 35636.375
B29: Tax Rate | C29: =C28/C25 -> 0.21762318 | D29: =D28/D25 -> 0.24699551 | E29: =E28/E25 -> 0.25495763 | F29: =F28/F25 -> 0.25527891 | G29: =G28/G25 -> 0.25303959 | H29: =Assumption!$G$13 -> 0.24557896 | I29: =Assumption!$G$13 -> 0.24557896 | J29: =Assumption!$G$13 -> 0.24557896 | K29: =Assumption!$G$13 -> 0.24557896 | L29: =Assumption!$G$13 -> 0.24557896
B31: Net Profit | C31: =C25-C28 -> 20363.97 | D31: =D25-D28 -> 25783.83 | E31: =E25-E28 -> 34463.03 | F31: =F25-F28 -> 45006.75 | G31: =G25-G28 -> 54418.71 | H31: =H25-H28 -> 58716.412 | I31: =I25-I28 -> 68611.777 | J31: =J25-J28 -> 80174.789 | ... L31: =L25-L28 -> 109475.3
B33: Model does not separately account for minority interest, which explains the gap between modeled and reported consolidated PAT
C36: Actual | I36: Expected
B37: Report Date | C37: Mar-21 | D37: Mar-22 | E37: Mar-23 | F37: Mar-24 | G37: Mar-25 | H37: Mar-26 | I37: Mar-27 | J37: Mar-28 | K37: Mar-29 | L37: Mar-30
B38: Balance Sheet
B39: Liabilities
B40: Equity Capital | C40: 1383 | D40: 1390 | E40: 1397 | F40: 1405 | G40: 1425 | H40: 1432 | I40: =H40*(1+I41) -> 1442.0157 | J40: =I40*(1+J41) -> 1452.1015 | K40: =J40*(1+K41) -> 1462.2579 | L40: =K40*(1+L41) -> 1472.4852
B41: % Change in Equity Capital | D41: =(D40/C40)-1 -> 0.0050614606 | E41: =(E40/D40)-1 -> 0.0050359712 | F41: =(F40/E40)-1 -> 0.0057265569 | G41: =(G40/F40)-1 -> 0.014234875 | H41: =(H40/G40)-1 -> 0.0049122807 | I41: =Assumption!$G$19 -> 0.006994229 | J41: =Assumption!$G$19 -> 0.006994229 | K41: =Assumption!$G$19 -> 0.006994229 | L41: =Assumption!$G$19 -> 0.006994229
B43: Reserves | C43: 156204 | D43: 180663 | E43: 213101 | F43: 254739 | G43: 312481 | H43: 361628 | I43: =(H43+I31)-(Assumption!$G$24*'Financial Statement'!I31) -> 420536.27 | J43: =(I43+J31)-(Assumption!$G$24*'Financial Statement'!J31) -> 489372.24 | K43: =(J43+K31)-(Assumption!$G$24*'Financial Statement'!K31) -> 569809.01 | L43: =(K43+L31)-(Assumption!$G$24*'Financial Statement'!L31) -> 663801.63
B44: % change in Reserves | D44: =(D43/C43)-1 -> 0.1565837 | E44: =(E43/D43)-1 -> 0.17954977 | F44: =(F43/E43)-1 -> 0.19539092 | G44: =(G43/F43)-1 -> 0.22667122 | H44: =(H43/G43)-1 -> 0.15727996 | I44: =(I43/H43)-1 -> 0.16289743 | J44: =(J43/I43)-1 -> 0.16368617 | K44: =(K43/J43)-1 -> 0.16436724 | L44: =(L43/K43)-1 -> 0.16495461
B46: Deposits | C46: 959940 | D46: 1091366 | E46: 1210832 | F46: 1443580 | G46: 1641637 | H46: 1830020 | I46: =H46*(1+I47) -> 2082763.5 | J46: =I46*(1+J47) -> 2370413.3 | K46: =J46*(1+K47) -> 2697790.4 | L46: =K46*(1+L47) -> 3070381.4
B47: % change in Deposits | D47: =(D46/C46)-1 -> 0.13691064 | E47: =(E46/D46)-1 -> 0.10946465 | F47: =(F46/E46)-1 -> 0.19222155 | G47: =(G46/F46)-1 -> 0.13719849 | H47: =(H46/G46)-1 -> 0.11475314 | I47: =Assumption!$G$28 -> 0.13810969 | J47: =Assumption!$G$28 -> 0.13810969 | K47: =Assumption!$G$28 -> 0.13810969 | L47: =Assumption!$G$28 -> 0.13810969
B49: Borrowings | C49: 143900 | D49: 161603 | E49: 189062 | F49: 207428 | G49: 218883 | H49: 220264 | I49: =H49*(1+I50) -> 240158.92 | J49: =I49*(1+J50) -> 261850.81 | K49: =J49*(1+K50) -> 285501.98 | L49: =K49*(1+L50) -> 311289.4
B50: Borrowings Rate | D50: =(D49/C49)-1 -> 0.12302293 | E50: =(E49/D49)-1 -> 0.1699164 | F50: =(F49/E49)-1 -> 0.097142736 | G50: =(G49/F49)-1 -> 0.055223981 | H50: =(H49/G49)-1 -> 0.0063093068 | I50: =Assumption!$G$29 -> 0.090323071 | J50: =Assumption!$G$29 -> 0.090323071 | K50: =Assumption!$G$29 -> 0.090323071 | L50: =Assumption!$G$29 -> 0.090323071
B52: Other Liabilities | C52: 312385 | D52: 317616 | E52: 344099 | F52: 456911 | G52: 467815 | H52: 501153 | I52: =(H52)*(1+I53) -> 553583.75 | J52: =(I52)*(1+J53) -> 611499.82 | K52: =(J52)*(1+K53) -> 675475.09 | L52: =(K52)*(1+L53) -> 746143.46
B53: Change rates in Other Liabilities | D53: =(D52/C52)-1 -> 0.016745362 | E53: =(E52/D52)-1 -> 0.08338056 | F53: =(F52/E52)-1 -> 0.32784751 | G53: =(G52/F52)-1 -> 0.023864604 | H53: =(H52/G52)-1 -> 0.071263213 | I53: =Assumption!$G$30 -> 0.10462025 | J53: =Assumption!$G$30 -> 0.10462025 | K53: =Assumption!$G$30 -> 0.10462025 | L53: =Assumption!$G$30 -> 0.10462025
B55: Total Liabilities and Equity | C55: =(C40+C43+C46+C49+C52) -> 1573812 | D55: =(D40+D43+D46+D49+D52) -> 1752638 | E55: =(E40+E43+E46+E49+E52) -> 1958491 | F55: =(F40+F43+F46+F49+F52) -> 2364063 | G55: =(G40+G43+G46+G49+G52) -> 2642241 | H55: =(H40+H43+H46+H49+H52) -> 2914497 | I55: =(I40+I43+I46+I49+I52) -> 3298484.5 | J55: =(J40+J43+J46+J49+J52) -> 3734588.3 | ... L55: =(L40+L43+L46+L49+L52) -> 4793088.4
B57: Assets
B58: Fixed Assets | C58: 10809 | D58: 10707 | E58: 11070 | F58: 15714 | G58: 24272 | H58: 27970 | I58: =(H58*(1+I59))-(I22) -> 28321.054 | J58: =(I58*(1+J59))-(J22) -> 29644.302 | K58: =(J58*(1+K59))-(K22) -> 30548.442 | L58: =(K58*(1+L59))-(L22) -> 30843.32
B59: CAPEX % | C59: NA | D59: =ABS('Data Sheet'!B38/'Financial Statement'!C58) -> 0.15616616 | E59: =ABS('Data Sheet'!C38/'Financial Statement'!D58) -> 0.17371813 | F59: =ABS('Data Sheet'!D38/'Financial Statement'!E58) -> 0.2229449 | G59: =ABS('Data Sheet'!E38/'Financial Statement'!F58) -> 0.23412244 | H59: =ABS('Data Sheet'!F38/'Financial Statement'!G58) -> 0.19652274 | I59: =ABS('Data Sheet'!G38/'Financial Statement'!H58) -> 0.13335717 | J59: =Assumption!$G$35 -> 0.18613859 | K59: =Assumption!$G$35 -> 0.18613859 | L59: =Assumption!$G$35 -> 0.18613859
B60: Depraciation | C60: =C22 -> 1340.07 | D60: =D22 -> 1330.01 | E60: =E22 -> 1514.56 | F60: =F22 -> 1935.21 | G60: =G22 -> 2627.32 | H60: =H22 -> 2891.6258 | I60: =I22 -> 3378.946 | J60: =J22 -> 3948.3934 | ... L60: =L22 -> 5391.365
B62: Net Fixed Assets | C62: =C58 -> 10809 | D62: =D58 -> 10707 | E62: =E58 -> 11070 | F62: =F58 -> 15714 | G62: =G58 -> 24272 | H62: =H58 -> 27970 | I62: =I58 -> 28321.054 | J62: =J58 -> 29644.302 | ... L62: =L58 -> 30843.32
...

Sheet Assumption
E3: Financial Statement Assumption | G3: Choose
E4: 1 | F4: Growth % | G4: 0.1685281 | H4: =_xlfn.XLOOKUP(G4,G5:G7,F5:F7,,0) -> BASE CASE | I4: Keeping the growth % as average of last 4year's growth percentage
F5: BULL CASE | G5: 0.1885
F6: BASE CASE | G6: =AVERAGE('Financial Statement'!D11:G11) -> 0.1685281
F7: BEAR CASE | G7: 0.1485
E9: 2 | F9: Cost to Income ratio | G9: =AVERAGE('Financial Statement'!C14:G14) -> 0.48282709 | H9: COIR is fluctuating over time so took their average
E11: 3 | F11: Interest | G11: =AVERAGE('Financial Statement'!C20:G20) -> 0.28267661 | H11: Interest, tax, and depreciation rates are forecast using their historical averages.
E13: 4 | F13: Tax rates | G13: =AVERAGE('Financial Statement'!C29:G29) -> 0.24557896
E15: 5 | F15: Depreciation Rate | G15: =AVERAGE('Financial Statement'!C23:G23) -> 0.0084001967
E17: Balance Sheet Assumption
E18: Liabilities
E19: 1 | F19: Equity Capital | G19: =AVERAGE('Financial Statement'!D41:H41) -> 0.006994229 | H19: Average historical growth %
E20: 2 | F20: Borrowings
E21: 3 | F21: Other Liabilities
E22: 4 | F22: Investments
E23: 5 | F23: Other Assets
E24: 6 | F24: Dividend Payout ratio | G24: =AVERAGE('Data Sheet'!B25:G25) -> 0.14142623
E25: 7 | F25: Reserves | G25: Are taken as "(Opening reserves+forecasted netprofit)-(Average Dividend payout ratio*forecasted net profit)
E28: 8 | F28: Deposits growth rate | G28: =AVERAGE('Financial Statement'!D47:H47) -> 0.13810969
E29: 9 | F29: Average Borrowing rate | G29: =AVERAGE('Financial Statement'!D50:H50) -> 0.090323071
E30: 10 | F30: Change rates in Other Liabilities | G30: =AVERAGE('Financial Statement'!D53:H53) -> 0.10462025
E32: Assets
E33: 1 | F33: Fixed Assets | G33: "=(Opening Asset+Capital expenditure)-(Depreciation))
F34: Capital expenditure % | G34: Previous year Fixed assets - capital expenditure(Assets purchased)
F35: CAPEX avg till Mar27 | G35: =AVERAGE('Financial Statement'!D59:I59) -> 0.18613859
F36: Depreciation rate | G36: =G15 -> 0.0084001967
E38: 2 | F38: Investments | G38: =AVERAGE('Financial Statement'!D64:H64) -> 0.10638202 | H38: Average % change in Investment
E39: 3 | F39: Other Assets | G39: Other Assets(t) = Total Liabilities & Equity(t) − Fixed Assets(t) − Investments(t)

Sheet Sheet3
B6: PROFIT AND LOSS STATEMENT
C7: Actual | E7: Expected
B8: Report Date | C8: Mar-25 | D8: Mar-26 | E8: Mar-27 | F8: Mar-28 | G8: Mar-29 | H8: Mar-30
B10: Total Operating Income | C10: 294586.93 | D10: 344233.11 | E10: 402246.06 | F10: 470035.82 | G10: 549250.06 | H10: 641814.13
B12: Operating Expenses | C12: 130078.42 | D12: 166205.07 | E12: 194215.29 | F12: 226946.03 | G12: 265192.81 | H12: 309885.25
B14: Operating Profit | C14: 164508.51 | D14: 178028.04 | E14: 208030.77 | F14: 243089.8 | G14: 284057.26 | H14: 331928.89
B16: Interest | C16: 89027.65 | D16: 97306.648 | E16: 113705.55 | F16: 132868.13 | G16: 155260.15 | H16: 181425.85
B18: Depreciation | C18: 2627.32 | D18: 2891.6258 | E18: 3378.946 | F18: 3948.3934 | G18: 4613.8086 | H18: 5391.365
B20: Profit Before Tax | C20: 72853.54 | D20: 77829.765 | E20: 90946.267 | F20: 106273.27 | G20: 124183.3 | H20: 145111.68
B22: Tax | C22: 18434.83 | D22: 19113.353 | E22: 22334.49 | F22: 26098.479 | G22: 30496.806 | H22: 35636.375
B24: Net Profit | C24: 54418.71 | D24: 58716.412 | E24: 68611.777 | F24: 80174.789 | G24: 93686.494 | H24: 109475.3
B26: Model does not separately account for minority interest, which explains the gap between modeled and reported consolidated PAT
B30: BALANCE SHEET
C31: Actual | E31: Expected
B32: Report Date | C32: Mar-25 | D32: Mar-26 | E32: Mar-27 | F32: Mar-28 | G32: Mar-29 | H32: Mar-30
B34: Liabilities
B35: Equity Capital | C35: 1425 | D35: 1432 | E35: =D35*(1+E36) -> 1442.0157 | F35: =E35*(1+F36) -> 1452.1015 | G35: =F35*(1+G36) -> 1462.2579 | H35: =G35*(1+H36) -> 1472.4852
B36: % Change | C36: 0 | D36: =(D35/C35)-1 -> 0.0049122807 | E36: =Assumption!$G$19 -> 0.006994229 | F36: =Assumption!$G$19 -> 0.006994229 | G36: =Assumption!$G$19 -> 0.006994229 | H36: =Assumption!$G$19 -> 0.006994229
B38: Reserves | C38: 312481 | D38: 361628 | E38: =(D38+E27)-(Assumption!$G$24*'Financial Statement'!E30) -> 361628 | F38: =(E38+F27)-(Assumption!$G$24*'Financial Statement'!F30) -> 361628 | G38: =(F38+G27)-(Assumption!$G$24*'Financial Statement'!G30) -> 361628 | H38: =(G38+H27)-(Assumption!$G$24*'Financial Statement'!H30) -> 361628
B39: % change | C39: 0 | D39: =(D38/C38)-1 -> 0.15727996 | E39: =(E38/D38)-1 -> 0 | F39: =(F38/E38)-1 -> 0 | G39: =(G38/F38)-1 -> 0 | H39: =(H38/G38)-1 -> 0
B41: Deposits | C41: 1641637 | D41: 1830020 | E41: =D41*(1+E42) -> 2082763.5 | F41: =E41*(1+F42) -> 2370413.3 | G41: =F41*(1+G42) -> 2697790.4 | H41: =G41*(1+H42) -> 3070381.4
B42: % change | C42: 0 | D42: =(D41/C41)-1 -> 0.11475314 | E42: =Assumption!$G$28 -> 0.13810969 | F42: =Assumption!$G$28 -> 0.13810969 | G42: =Assumption!$G$28 -> 0.13810969 | H42: =Assumption!$G$28 -> 0.13810969
B44: Borrowings | C44: 218883 | D44: 220264 | E44: =D44*(1+E45) -> 240158.92 | F44: =E44*(1+F45) -> 261850.81 | G44: =F44*(1+G45) -> 285501.98 | H44: =G44*(1+H45) -> 311289.4
B45: Borrowings Rate | C45: 0 | D45: =(D44/C44)-1 -> 0.0063093068 | E45: =Assumption!$G$29 -> 0.090323071 | F45: =Assumption!$G$29 -> 0.090323071 | G45: =Assumption!$G$29 -> 0.090323071 | H45: =Assumption!$G$29 -> 0.090323071
B47: Other Liabilities | C47: 467815 | D47: 501153 | E47: =(D47)*(1+E48) -> 553583.75 | F47: =(E47)*(1+F48) -> 611499.82 | G47: =(F47)*(1+G48) -> 675475.09 | H47: =(G47)*(1+H48) -> 746143.46
B48: %Change | C48: 0 | D48: =(D47/C47)-1 -> 0.071263213 | E48: =Assumption!$G$30 -> 0.10462025 | F48: =Assumption!$G$30 -> 0.10462025 | G48: =Assumption!$G$30 -> 0.10462025 | H48: =Assumption!$G$30 -> 0.10462025
B50: Total Liabilities and Equity | C50: =(C35+C38+C41+C44+C47) -> 2642241 | D50: =(D35+D38+D41+D44+D47) -> 2914497 | E50: =(E35+E38+E41+E44+E47) -> 3239576.2 | F50: =(F35+F38+F41+F44+F47) -> 3606844.1 | G50: =(G35+G38+G41+G44+G47) -> 4021857.7 | H50: =(H35+H38+H41+H44+H47) -> 4490914.7
B52: Assets
B53: Fixed Assets | C53: ='Financial Statement'!G62 -> 24272 | D53: ='Financial Statement'!H62 -> 27970 | E53: ='Financial Statement'!I62 -> 28321.054 | F53: ='Financial Statement'!J62 -> 29644.302 | G53: ='Financial Statement'!K62 -> 30548.442 | H53: ='Financial Statement'!L62 -> 30843.32
B55: Investments | C55: ='Financial Statement'!G63 -> 886377 | D55: ='Financial Statement'!H63 -> 870720 | E55: ='Financial Statement'!I63 -> 963348.95 | F55: ='Financial Statement'!J63 -> 1065832 | G55: ='Financial Statement'!K63 -> 1179217.3 | H55: ='Financial Statement'!L63 -> 1304664.8
B57: Other Assets | C57: ='Financial Statement'!G65 -> 1731593 | D57: ='Financial Statement'!H65 -> 2015808 | E57: ='Financial Statement'!I65 -> 2306814.5 | F57: ='Financial Statement'!J65 -> 2639112.1 | G57: ='Financial Statement'!K65 -> 3020273 | H57: ='Financial Statement'!L65 -> 3457580.2
B59: Total Assets | C59: ='Financial Statement'!G68 -> 2642242 | D59: ='Financial Statement'!H68 -> 2914498 | E59: ='Financial Statement'!I68 -> 3298484.5 | F59: ='Financial Statement'!J68 -> 3734588.3 | G59: ='Financial Statement'!K68 -> 4230038.7 | H59: ='Financial Statement'!L68 -> 4793088.4
