Workbook
Name UPDATE: 'Data Sheet'!#REF!

Sheet Data Sheet
A1: ITC Limited
C4: Equity Research on ITC limited by Aban Keot
F6: Date 26/04/2026
A7: About: Established in 1910, ITC is the largest cigarette manufacturer and seller in the country. ITC operates in four business segments at present — FMCG Cigarettes, FMCG Others, Paperboards, Paper and Packaging, and Agri Business.
A14: Number of shares = | B14: 1253 | C14: cr approx
A15: Face Value= | B15: ₹ 1
A16: Current Price= ₹ | B16: 301.45
A17: Market Capitalization = | B17: 377889 | C17: Cr | E17: Book value | F17: ₹ 56.7
A18: Dividend frequency = Twice a year- Feb & May | E18: Dividend Yield = | F18: 0.0476
A21: PROFIT & LOSS | G21: Figures in ₹ Crores (Unless stated)
A22: Report Date | B22: 43921 | C22: 44286 | D22: 44651 | E22: 45016 | F22: 45382 | G22: 45747
A23: Sales | B23: 49387.7 | C23: 49257.45 | D23: 60644.54 | E23: 70919.03 | F23: 67931.94 | G23: 75323.34
A24: Raw Material Cost | B24: 18048.6 | C24: 20776.71 | D24: 27071.07 | E24: 29364.36 | F24: 27348.57 | G24: 32704.37
A25: Change in Inventory | B25: 703.13 | C25: 645.27 | D25: 686 | E25: 358.59 | F25: 367.77 | G25: 725.65
A26: Power and Fuel | B26: 780.85 | C26: 699.56 | D26: 889.77 | E26: 1232.34 | F26: 952.9 | G26: 975.35
A27: Other Mfr. Exp | B27: 1908.29 | C27: 1587.18 | D27: 1887.67 | E27: 2327.8 | F27: 2183.76 | G27: 2345.36
A28: Employee Cost | B28: 4295.79 | C28: 4463.33 | D28: 4890.55 | E28: 5736.22 | F28: 5548.53 | G28: 6169.78
A29: Selling and admin | B29: 4488.63 | C29: 4236.77 | D29: 4858.38 | E29: 5604.08 | F29: 5312.45 | G29: 5793.29
A30: Other Expenses | B30: 1225.13 | C30: 1074.39 | D30: 1109.95 | E30: 1308.56 | F30: 1765.97 | G30: 2221.39
A31: Other Income | B31: 2417.32 | C31: 2576.95 | D31: 1909.72 | E31: 2097.64 | F31: 3330.45 | G31: 17794.88
A32: Depreciation | B32: 1644.91 | C32: 1645.59 | D32: 1732.41 | E32: 1809.01 | F32: 1518.05 | G32: 1646.32
A33: Interest | B33: 81.38 | C33: 57.97 | D33: 59.99 | E33: 77.77 | F33: 39.11 | G33: 45.06
... A37: Dividend Amount | B37: 12476.58 | C37: 13231.96 | D37: 14171.8 | E37: 19263.4 | F37: 17166.46 | G37: 17957.73
A41: BALANCE SHEET
A42: Report Date | B42: 43921 | C42: 44286 | D42: 44651 | E42: 45016 | F42: 45382 | G42: 45747
A43: Equity Capital | B43: 1229 | C43: 1231 | D43: 1232 | E43: 1243 | F43: 1248 | G43: 1251
A44: Reserves | B44: 64044 | C44: 59116 | D44: 61223 | E44: 67912 | F44: 73259 | G44: 68779
A45: Borrowings | B45: 277 | C45: 271 | D45: 249 | E45: 306 | F45: 303 | G45: 285
A46: Long term Borrowings | B46: 6 | C46: 6 | D46: 5 | E46: 3 | F46: 2 | G46: 0
A47: Short term Borrowings | B47: 1 | C47: 4 | D47: 1 | E47: 35 | F47: 10 | G47: 91
A48: Lease Liabilities | B48: 268 | C48: 261 | D48: 244 | E48: 267 | F48: 292 | G48: 193
A49: Other Borrowings | B49: 2 | C49: 0 | D49: 0 | E49: 0 | F49: 0 | G49: 0
A50: Other Liabilities | B50: 11760 | C50: 13143 | D50: 14491 | E50: 16370 | F50: 16944 | G50: 17688
A51: Non controlling int | B51: 377 | C51: 347 | D51: 366 | E51: 384 | F51: 383 | G51: 368
A52: Trade Payables | B52: 3630 | C52: 4319 | D52: 4417 | E52: 4659 | F52: 4798 | G52: 4807
A53: Advance from Customers | B53: 703 | C53: 811 | D53: 1278 | E53: 1295 | F53: 886 | G53: 1264
... A80: Face value | B80: 1 | C80: 1 | D80: 1 | E80: 1 | F80: 1 | G80: 1
A87: CASH FLOW:
A88: Report Date | B88: 43921 | C88: 44286 | D88: 44651 | E88: 45016 | F88: 45382 | G88: 45747
A89: Cash from Operating Activity | B89: 14690 | C89: 12527 | D89: 15776 | E89: 18878 | F89: 17179 | G89: 17627
...

Sheet Financial Statement
E4: Equity Research on ITC limited by Aban Keot
M6: Figures in ₹ Crores (Unless stated)
C7: Actual | I7: Expected
B8: Report Date | C8: 43921 | D8: 44286 | E8: 44651 | F8: 45016 | G8: 45382 | H8: 45747 | I8: 46107 | J8: 46473 | K8: 46840 | L8: 47206 | M8: 47572
B9: Income Statement
B11: Sales | C11: 49387.7 | D11: 49257.45 | E11: 60644.54 | F11: 70919.03 | G11: 67931.94 | H11: 75323.34 | I11: =H11*(1+I12) -> 82323.069 | J11: =I11*(1+J12) -> 89973.277 | K11: =J11*(1+K12) -> 98334.411 | L11: =K11*(1+L12) -> 107472.54 | M11: =L11*(1+M12) -> 117459.86
B12: Sales Growth % | D12: =D11/C11-1 -> -0.0026372963 | E12: =E11/D11-1 -> 0.23117498 | F12: =F11/E11-1 -> 0.16942152 | G12: =G11/F11-1 -> -0.042119724 | H12: =H11/G11-1 -> 0.10880596 | I12: =Assumptions!$D$3 -> 0.092929087 | J12: =Assumptions!$D$3 -> 0.092929087 | K12: =Assumptions!$D$3 -> 0.092929087 | L12: =Assumptions!$D$3 -> 0.092929087 | M12: =Assumptions!$D$3 -> 0.092929087
B14: COGS | C14: =SUM('Data Sheet'!B24:B27) -> 21440.87 | D14: =SUM('Data Sheet'!C24:C27) -> 23708.72 | E14: =SUM('Data Sheet'!D24:D27) -> 30534.51 | F14: =SUM('Data Sheet'!E24:E27) -> 33283.09 | G14: =SUM('Data Sheet'!F24:F27) -> 30853 | H14: =SUM('Data Sheet'!G24:G27) -> 36750.73 | I14: =I11*I15 -> 38833.831 | J14: =J11*J15 -> 42442.623 | K14: =K11*K15 -> 46386.778 | L14: =L11*L15 -> 50697.459 | M14: =M11*M15 -> 55408.727
B15: COGS % of Sales | C15: =C14/C11 -> 0.4341338 | D15: =D14/D11 -> 0.48132252 | E15: =E14/E11 -> 0.50349974 | F15: =F14/F11 -> 0.46931113 | G15: =G14/G11 -> 0.45417516 | H15: =H14/H11 -> 0.48790627 | I15: =Assumptions!$D$11 -> 0.47172477 | J15: =Assumptions!$D$11 -> 0.47172477 | K15: =Assumptions!$D$11 -> 0.47172477 | L15: =Assumptions!$D$11 -> 0.47172477 | M15: =Assumptions!$D$11 -> 0.47172477
B17: Gross Profit | C17: =C11-C14 -> 27946.83 | D17: =D11-D14 -> 25548.73 | E17: =E11-E14 -> 30110.03 | F17: =F11-F14 -> 37635.94 | G17: =G11-G14 -> 37078.94 | H17: =H11-H14 -> 38572.61 | I17: =I11-I14 -> 43489.238 | J17: =J11-J14 -> 47530.653 | ... M17: =M11-M14 -> 62051.136
B18: Gross Margin | C18: =C17/C11 -> 0.5658662 | D18: =D17/D11 -> 0.51867748 | E18: =E17/E11 -> 0.49650026 | F18: =F17/F11 -> 0.53068887 | G18: =G17/G11 -> 0.54582484 | H18: =H17/H11 -> 0.51209373 | I18: =1-I15 -> 0.52827523 | J18: =1-J15 -> 0.52827523 | K18: =1-K15 -> 0.52827523 | L18: =1-L15 -> 0.52827523 | M18: =1-M15 -> 0.52827523
B20: Operating Expenses | C20: =SUM('Data Sheet'!B28:B30) -> 10009.55 | D20: =SUM('Data Sheet'!C28:C30) -> 9774.49 | E20: =SUM('Data Sheet'!D28:D30) -> 10858.88 | F20: =SUM('Data Sheet'!E28:E30) -> 12648.86 | G20: =SUM('Data Sheet'!F28:F30) -> 12626.95 | H20: =SUM('Data Sheet'!G28:G30) -> 14184.46 | I20: =I11*I21 -> 15541.425 | J20: =J11*J21 -> 16985.675 | K20: =K11*K21 -> 18564.138 | L20: =L11*L21 -> 20289.287 | M20: =M11*M21 -> 22174.752
B21: OE % of Sales | C21: =C20/C11 -> 0.20267293 | D21: =D20/D11 -> 0.19843678 | E21: =E20/E11 -> 0.17905783 | F21: =F20/F11 -> 0.17835636 | G21: =G20/G11 -> 0.18587648 | H21: =H20/H11 -> 0.18831427 | I21: =Assumptions!$D$18 -> 0.18878578 | J21: =Assumptions!$D$18 -> 0.18878578 | K21: =Assumptions!$D$18 -> 0.18878578 | L21: =Assumptions!$D$18 -> 0.18878578 | M21: =Assumptions!$D$18 -> 0.18878578
B23: EBITDA | C23: =C17-C20 -> 17937.28 | D23: =D17-D20 -> 15774.24 | E23: =E17-E20 -> 19251.15 | F23: =F17-F20 -> 24987.08 | G23: =G17-G20 -> 24451.99 | H23: =H17-H20 -> 24388.15 | I23: =I17-I20 -> 27947.814 | J23: =J17-J20 -> 30544.978 | ... M23: =M17-M20 -> 39876.385
B24: EBITDAMargin | C24: =C23/C11 -> 0.36319326 | D24: =D23/D11 -> 0.32024069 | E24: =E23/E11 -> 0.31744243 | F24: =F23/F11 -> 0.35233251 | G24: =G23/G11 -> 0.35994835 | H24: =H23/H11 -> 0.32377946 | I24: =I23/I11 -> 0.33948945 | J24: =J23/J11 -> 0.33948945 | ... M24: =M23/M11 -> 0.33948945
B26: Depreciation | C26: ='Data Sheet'!B32 -> 1644.91 | D26: ='Data Sheet'!C32 -> 1645.59 | E26: ='Data Sheet'!D32 -> 1732.41 | F26: ='Data Sheet'!E32 -> 1809.01 | G26: ='Data Sheet'!F32 -> 1518.05 | H26: ='Data Sheet'!G32 -> 1646.32 | I26: =I11*I27 -> 2263.7757 | J26: =J11*J27 -> 2474.1463 | K26: =K11*K27 -> 2704.0664 | L26: =L11*L27 -> 2955.3529 | M26: =M11*M27 -> 3229.9911
B27: Depreciation % of Sales | C27: =C26/C11 -> 0.033306066 | D27: =D26/D11 -> 0.033407941 | E27: =E26/E11 -> 0.028566628 | F27: =F26/F11 -> 0.025508104 | G27: =G26/G11 -> 0.022346631 | H27: =H26/H11 -> 0.021856705 | I27: =Assumptions!$D$22 -> 0.027498679 | J27: =Assumptions!$D$22 -> 0.027498679 | K27: =Assumptions!$D$22 -> 0.027498679 | L27: =Assumptions!$D$22 -> 0.027498679 | M27: =Assumptions!$D$22 -> 0.027498679
B29: EBIT | C29: =C23-C26 -> 16292.37 | D29: =D23-D26 -> 14128.65 | E29: =E23-E26 -> 17518.74 | F29: =F23-F26 -> 23178.07 | G29: =G23-G26 -> 22933.94 | H29: =H23-H26 -> 22741.83 | I29: =I23-I26 -> 25684.038 | J29: =J23-J26 -> 28070.832 | ... M29: =M23-M26 -> 36646.394
B30: EBIT % of Sales | C30: =C29/C11 -> 0.3298872 | D30: =D29/D11 -> 0.28683275 | E30: =E29/E11 -> 0.2888758 | F30: =F29/F11 -> 0.32682441 | G30: =G29/G11 -> 0.33760172 | H30: =H29/H11 -> 0.30192275 | I30: =I29/I11 -> 0.31199077 | J30: =J29/J11 -> 0.31199077 | ... M30: =M29/M11 -> 0.31199077
B32: Interest | C32: ='Data Sheet'!B33 -> 81.38 | D32: ='Data Sheet'!C33 -> 57.97 | E32: ='Data Sheet'!D33 -> 59.99 | F32: ='Data Sheet'!E33 -> 77.77 | G32: ='Data Sheet'!F33 -> 39.11 | H32: ='Data Sheet'!G33 -> 45.06 | I32: =H32+(1*I33) -> 45.061014 | J32: =I32*(1+J33) -> 45.106709 | K32: =J32*(1+K33) -> 45.15245 | L32: =K32*(1+L33) -> 45.198238 | M32: =L32*(1+M33) -> 45.244072
B33: Interest % of Sales | C33: =C32/C11 -> 0.0016477787 | D33: =D32/D11 -> 0.0011768778 | E33: =E32/E11 -> 0.00098920694 | F33: =F32/F11 -> 0.0010966027 | G33: =G32/G11 -> 0.00057572329 | H33: =H32/H11 -> 0.00059822095 | I33: =Assumptions!$D$25 -> 0.0010140684 | J33: =Assumptions!$D$25 -> 0.0010140684 | K33: =Assumptions!$D$25 -> 0.0010140684 | L33: =Assumptions!$D$25 -> 0.0010140684 | M33: =Assumptions!$D$25 -> 0.0010140684
B35: EBT | C35: =C29-C32 -> 16210.99 | D35: =D29-D32 -> 14070.68 | E35: =E29-E32 -> 17458.75 | F35: =F29-F32 -> 23100.3 | G35: =G29-G32 -> 22894.83 | H35: =H29-H32 -> 22696.77 | I35: =I29-I32 -> 25638.977 | J35: =J29-J32 -> 28025.725 | ... M35: =M29-M32 -> 36601.149
B36: EBT % of Sales | C36: =C35/C11 -> 0.32823942 | D36: =D35/D11 -> 0.28565588 | E36: =E35/E11 -> 0.28788659 | F36: =F35/F11 -> 0.32572781 | G36: =G35/G11 -> 0.337026 | H36: =H35/H11 -> 0.30132453 | I36: =I35/I11 -> 0.3114434 | J36: =J35/J11 -> 0.31148944 | ... M36: =M35/M11 -> 0.31160558
B38: Tax | C38: ='Data Sheet'!B35 -> 4441.79 | D38: ='Data Sheet'!C35 -> 4555.29 | E38: ='Data Sheet'!D35 -> 5237.34 | F38: ='Data Sheet'!E35 -> 6438.4 | G38: ='Data Sheet'!F35 -> 6209.46 | H38: ='Data Sheet'!G35 -> 6890.47 | I38: =H38*(1+I39) -> 8901.6209 | J38: =I38*(1+J39) -> 11499.775 | K38: =J38*(1+K39) -> 14856.263 | L38: =K38*(1+L39) -> 19192.424 | M38: =L38*(1+M39) -> 24794.199
B39: Effective Tax Rates | C39: =C38/C35 -> 0.27399869 | D39: =D38/D35 -> 0.32374342 | E39: =E38/E35 -> 0.29998368 | F39: =F38/F35 -> 0.278715 | G39: =G38/G35 -> 0.27121669 | H39: =H38/H35 -> 0.30358813 | I39: =Assumptions!$D$28 -> 0.29187427 | J39: =Assumptions!$D$28 -> 0.29187427 | K39: =Assumptions!$D$28 -> 0.29187427 | L39: =Assumptions!$D$28 -> 0.29187427 | M39: =Assumptions!$D$28 -> 0.29187427
B41: Net Profit | C41: =C35-C38 -> 11769.2 | D41: =D35-D38 -> 9515.39 | E41: =E35-E38 -> 12221.41 | F41: =F35-F38 -> 16661.9 | G41: =G35-G38 -> 16685.37 | H41: =H35-H38 -> 15806.3 | I41: =I35-I38 -> 16737.356 | J41: =J35-J38 -> 16525.951 | ... M41: =M35-M38 -> 11806.95
B42: Net Margin | C42: =C41/C11 -> 0.23830225 | D42: =D41/D11 -> 0.19317667 | E42: =E41/E11 -> 0.20152531 | F42: =F41/F11 -> 0.23494258 | G42: =G41/G11 -> 0.24561892 | H42: =H41/H11 -> 0.20984598 | I42: =I41/I11 -> 0.20331307 | J42: =J41/J11 -> 0.18367621 | ... M42: =M41/M11 -> 0.10051902
B44: Number of Shares in Cr | C44: ='Data Sheet'!$B$14 -> 1253 | D44: ='Data Sheet'!$B$14 -> 1253 | E44: ='Data Sheet'!$B$14 -> 1253 | F44: ='Data Sheet'!$B$14 -> 1253 | G44: ='Data Sheet'!$B$14 -> 1253 | H44: ='Data Sheet'!$B$14 -> 1253 | I44: ='Data Sheet'!$B$14 -> 1253 | J44: ='Data Sheet'!$B$14 -> 1253 | ... M44: ='Data Sheet'!$B$14 -> 1253
B46: EPS | C46: =C41/C44 -> 9.3928172 | D46: =D41/D44 -> 7.5940862 | E46: =E41/E44 -> 9.7537191 | F46: =F41/F44 -> 13.297606 | G46: =G41/G44 -> 13.316337 | H46: =H41/H44 -> 12.614765 | I46: =I41/I44 -> 13.357826 | J46: =J41/J44 -> 13.189107 | ... M46: =M41/M44 -> 9.4229453
B51: BALANCE SHEET | M51: Figures in ₹ Crores (Unless stated)
B52: Report Date | C52: 43921 | D52: 44286 | E52: 44651 | F52: 45016 | G52: 45382 | H52: 45747 | I52: 46107 | J52: 46473 | K52: 46840 | L52: 47206 | M52: 47572
B54: Equity Capital | C54: 1229 | D54: 1231 | E54: 1232 | F54: 1243 | G54: 1248 | H54: 1251
B55: Reserves | C55: 64044 | D55: 59116 | E55: 61223 | F55: 67912 | G55: 73259 | H55: 68779
A56: # | B56: Borrowings | C56: 277 | D56: 271 | E56: 249 | F56: 306 | G56: 303 | H56: 285
B57: Long term Borrowings | C57: 6 | D57: 6 | E57: 5 | F57: 3 | G57: 2 | H57: 0
A58: # | B58: Short term Borrowings | C58: 1 | D58: 4 | E58: 1 | F58: 35 | G58: 10 | H58: 91
B59: Lease Liabilities | C59: 268 | D59: 261 | E59: 244 | F59: 267 | G59: 292 | H59: 193
B60: Other Borrowings | C60: 2 | D60: 0 | E60: 0 | F60: 0 | G60: 0 | H60: 0
B61: Other Liabilities | C61: 11760 | D61: 13143 | E61: 14491 | F61: 16370 | G61: 16944 | H61: 17688
B62: Non controlling int | C62: 377 | D62: 347 | E62: 366 | F62: 384 | G62: 383 | H62: 368
...

Sheet Assumptions
A2: 1 | B2: Sales Assumption Type | D2: Rate
B3: Base Case | D3: =IF(B3=B6,C6,IF(B3=B7,C7,IF(B3=B8,C8))) -> 0.092929087
B5: Sales
B6: Bull Case | C6: =C8+20%*C8 -> 0.1115149
B7: Bear Case | C7: =C8-20%*C8 -> 0.07434327
B8: Base Case | C8: =AVERAGE('Financial Statement'!D12:H12) -> 0.092929087
A10: 2 | B10: Sales Assumption Type | D10: Rate
B11: Base Case | D11: =IF(B11=B13,C13,IF(B11=B14,C14,IF(B11=B15,C15))) -> 0.47172477
B12: COGS
B13: Bull Case | C13: =C15+20%*C15 -> 0.56606973
B14: Bear Case | C14: =C15-20%*C15 -> 0.37737982
B15: Base Case | C15: =AVERAGE('Financial Statement'!C15:H15) -> 0.47172477
A17: 3 | B17: Operating Expenses | D17: Rate
B18: Avg of OpEx % of Sales | D18: =AVERAGE('Financial Statement'!C21:H21) -> 0.18878578
A21: 4 | B21: Depreciation | D21: Rate
B22: Average of Dep % | D22: =AVERAGE('Financial Statement'!C27:H27) -> 0.027498679
A24: 4 | B24: Interest | D24: Rate | F24: I used 5-year average interest to normalize fluctuations, since ITC has low and stable leverage.
B25: Interest % average | D25: =AVERAGE('Financial Statement'!C33:H33) -> 0.0010140684
A27: 5 | B27: Tax | D27: Rate
B28: Average | D28: =AVERAGE('Financial Statement'!C39:H39) -> 0.29187427
A30: Calculating Capital expenditure | G30: Figures in ₹ Crores (Unless stated)
A31: Year | B31: 43921 | C31: 44286 | D31: 44651 | E31: 45016 | F31: 45382 | G31: 45747
A32: Historical Capex | B32: =-'Data Sheet'!B97 -> 2441 | C32: =-'Data Sheet'!C97 -> 1837 | D32: =-'Data Sheet'!D97 -> 2142 | E32: =-'Data Sheet'!E97 -> 2743 | F32: =-'Data Sheet'!F97 -> 3563 | G32: =-'Data Sheet'!G97 -> 2279
A34: Capex % of Revenue | B34: =B32/'Financial Statement'!C11 -> 0.049425262 | C34: =C32/'Financial Statement'!D11 -> 0.037293851 | D34: =D32/'Financial Statement'!E11 -> 0.035320575 | E34: =E32/'Financial Statement'!F11 -> 0.038677912 | F34: =F32/'Financial Statement'!G11 -> 0.052449555 | G34: =G32/'Financial Statement'!H11 -> 0.030256226
A36: Forecast Capex % | B36: =AVERAGE($B$34:$G$34) -> 0.040570563
A38: Year | B38: 46107 | C38: 46473 | D38: 46840 | E38: 47206 | F38: 47572
A39: Forecast Capex | B39: =$B$36*'Financial Statement'!I11 -> 3339.8933 | C39: =$B$36*'Financial Statement'!J11 -> 3650.2665 | D39: =$B$36*'Financial Statement'!K11 -> 3989.4825 | E39: =$B$36*'Financial Statement'!L11 -> 4360.2214 | F39: =$B$36*'Financial Statement'!M11 -> 4765.4128 | G39: =$B$36*'Financial Statement'!N11 -> 0
A42: Calculating Net Working Capital | G42: Figures in ₹ Crores (Unless stated)
A43: Year | B43: 43921 | C43: 44286 | D43: 44651 | E43: 45016 | F43: 45382 | G43: 45747
A44: Inventory | B44: ='Data Sheet'!B71 -> 8879 | C44: ='Data Sheet'!C71 -> 10397 | D44: ='Data Sheet'!D71 -> 10864 | E44: ='Data Sheet'!E71 -> 11771 | F44: ='Data Sheet'!F71 -> 14153 | G44: ='Data Sheet'!G71 -> 15638
A46: Trade Receiveable | B46: ='Data Sheet'!B72 -> 2562 | C46: ='Data Sheet'!C72 -> 2502 | D46: ='Data Sheet'!D72 -> 2462 | E46: ='Data Sheet'!E72 -> 2956 | F46: ='Data Sheet'!F72 -> 4026 | G46: ='Data Sheet'!G72 -> 4720
A48: Trade Payable | B48: ='Data Sheet'!B52 -> 3630 | C48: ='Data Sheet'!C52 -> 4319 | D48: ='Data Sheet'!D52 -> 4417 | E48: ='Data Sheet'!E52 -> 4659 | F48: ='Data Sheet'!F52 -> 4798 | G48: ='Data Sheet'!G52 -> 4807
A50: Net Working Capital | B50: =SUM(B44,B46)-B48 -> 7811 | C50: =SUM(C44,C46)-C48 -> 8580 | D50: =SUM(D44,D46)-D48 -> 8909 | E50: =SUM(E44,E46)-E48 -> 10068 | F50: =SUM(F44,F46)-F48 -> 13381 | G50: =SUM(G44,G46)-G48 -> 15551
A52: Change in WC | B52: NA | C52: =C50-B50 -> 769 | D52: =D50-C50 -> 329 | E52: =E50-D50 -> 1159 | F52: =F50-E50 -> 3313 | G52: =G50-F50 -> 2170
A54: NWC % of Sales | B54: =B50/'Financial Statement'!C11 -> 0.15815679 | C54: =C50/'Financial Statement'!D11 -> 0.17418685 | D54: =D50/'Financial Statement'!E11 -> 0.14690523 | E54: =E50/'Financial Statement'!F11 -> 0.14196472 | F54: =F50/'Financial Statement'!G11 -> 0.19697656 | G54: =G50/'Financial Statement'!H11 -> 0.20645659
A56: Forecast NWC % | B56: =AVERAGE(B54:G54) -> 0.17077446
A57: Year | B57: 46107 | C57: 46473 | D57: 46840 | E57: 47206 | F57: 47572
A58: Forecast NWC | B58: =$B$56*'Financial Statement'!I11 -> 14058.677 | C58: =$B$56*'Financial Statement'!J11 -> 15365.137 | D58: =$B$56*'Financial Statement'!K11 -> 16793.006 | E58: =$B$56*'Financial Statement'!L11 -> 18353.564 | F58: =$B$56*'Financial Statement'!M11 -> 20059.144
A60: Change if Forecaster NWC | B60: =B58-G50 -> -1492.3226 | C60: =C58-B58 -> 1306.4601 | D60: =D58-C58 -> 1427.8682 | E60: =E58-D58 -> 1560.5587 | F60: =F58-E58 -> 1705.58
A62: Cost of Equity
...

Sheet FCFF
F1: Figures in ₹ Crores (Unless stated)
A2: Item | B2: 46107 | C2: 46473 | D2: 46840 | E2: 47206 | F2: 47572
A3: FCFF Schedule
A4: EBIT | B4: ='Financial Statement'!I29 -> 25684.038 | C4: ='Financial Statement'!J29 -> 28070.832 | D4: ='Financial Statement'!K29 -> 30679.429 | E4: ='Financial Statement'!L29 -> 33530.44 | F4: ='Financial Statement'!M29 -> 36646.394
A5: Tax Rate | B5: ='Financial Statement'!I39 -> 0.29187427 | C5: ='Financial Statement'!J39 -> 0.29187427 | D5: ='Financial Statement'!K39 -> 0.29187427 | E5: ='Financial Statement'!L39 -> 0.29187427 | F5: ='Financial Statement'!M39 -> 0.29187427
A6: NOPAT | B6: =B4*(1-B5) -> 18187.528 | C6: =C4*(1-C5) -> 19877.679 | D6: =D4*(1-D5) -> 21724.893 | E6: =E4*(1-E5) -> 23743.768 | F6: =F4*(1-F5) -> 25950.254
A7: Depreciation & Amortization | B7: ='Financial Statement'!I26 -> 2263.7757 | C7: ='Financial Statement'!J26 -> 2474.1463 | D7: ='Financial Statement'!K26 -> 2704.0664 | E7: ='Financial Statement'!L26 -> 2955.3529 | F7: ='Financial Statement'!M26 -> 3229.9911
A8: Capital Expenditure (Capex) | B8: =Assumptions!B39 -> 3339.8933 | C8: =Assumptions!C39 -> 3650.2665 | D8: =Assumptions!D39 -> 3989.4825 | E8: =Assumptions!E39 -> 4360.2214 | F8: =Assumptions!F39 -> 4765.4128
A9: Change in Net Working Capital | B9: =Assumptions!B60 -> -1492.3226 | C9: =Assumptions!C60 -> 1306.4601 | D9: =Assumptions!D60 -> 1427.8682 | E9: =Assumptions!E60 -> 1560.5587 | F9: =Assumptions!F60 -> 1705.58
A10: FCFF | B10: =SUM(B6,B7)-(B8)-(B9) -> 18603.733 | C10: =SUM(C6,C7)-(C8)-(C9) -> 17395.098 | D10: =SUM(D6,D7)-(D8)-(D9) -> 19011.609 | E10: =SUM(E6,E7)-(E8)-(E9) -> 20778.34 | F10: =SUM(F6,F7)-(F8)-(F9) -> 22709.253
A12: Present Value of FCFF | B12: =B10/(1+$B$39)^1 -> 16759.78 | C12: =C10/(1+$B$39)^2 -> 14117.679 | D12: =D10/(1+$B$39)^3 -> 13900.279 | E12: =E10/(1+$B$39)^4 -> 13686.226 | F12: =F10/(1+$B$39)^5 -> 13475.469
A14: Present Value of forecasted FCFF | B14: =SUM(B12:F12) -> 71939.432 | C14: PV=(FCFF)/(1+WACC)n
A16: FCFF2031 | B16: =F10*(1+Assumptions!B78) -> 23844.715 | C16: FCFFn​ = FCFF in our final forecast year, Mar-30
A18: =A45 -> Terminal Value | B18: =B16/(B39-Assumptions!B78) -> 397262.81 | C18: FCFFn+1​ = FCFF in the following year, Mar-31
A19: Present Value of Terminal Value | B19: =B18/(1+$B$39)^5 -> 235732.23 | C19: WACC = | D19: =B39 -> 0.11002252
C20: g = perpetual growth rate
A22: Enterprise Value | B22: =B14+B19 -> 307671.66
A24: Equity Value | B24: =B22-'Financial Statement'!H56+'Financial Statement'!H87+'Financial Statement'!H80 -> 346118.66
A26: Equity value per share | B26: =B24/'Data Sheet'!B14 -> 276.23197
A30: Market Value and Share of Equity and Debt
A31: Market Value of Equity | B31: =Valuation!C8*Valuation!C6 -> 377716.85
A32: Market Value of Debt | B32: ='Financial Statement'!H56 -> 285
A33: Total Capital | B33: =SUM(B31:B32) -> 378001.85
A35: Equity Weight | B35: =B31/B33 -> 0.99924604
A37: Debt Weight | B37: =B32/B33 -> 0.00075396456
A39: WACC | B39: =(B35*Assumptions!B66)+(FCFF!B37*Assumptions!B73*(1-'Financial Statement'!H39)) -> 0.11002252 | C39: E/V = Equity Weight
C40: Ke = Cost of Equity
C41: D/V = Debt Weight
C42: Kd = Pre-tax Cost of Debt
C43: T = Tax Rate
A45: Terminal Value | B45: "=FCFF2031/WACC-g" | C45: FCFF 2031 = Mar-30 FCFF grown one more year
A46: Terminal growth should represent long-term sustainable growth, not the company's temporary high-growth period.For a mature company like ITC, we'd normally want a conservative long-term rate, generally below the economy's long-term nominal growth and, most importantly: g<WACC | C46: WACC = 11.00%
C47: g = perpetual growth rate

Sheet Valuation
B2: Select the FY for EPS Forward
B3: 46840 | C3: =INDEX('Financial Statement'!I46:M46, MATCH(B3,'Financial Statement'!I8:M8,0)) -> 12.592189
B4: Target P/E | C4: 20
B5: Target Price | C5: =C3*C4 -> 251.84379
B6: Current Price | C6: ='Data Sheet'!$B$16 -> 301.45
B8: Number of shares = | C8: 1253 | D8: cr (approx)
B9: Dividend Yield % | C9: ='Data Sheet'!F18 -> 0.0476
B11: Price Return % | C11: =(C5/C6)-1 -> -0.16455868
B13: Total Expected Return | C13: =C11+C9 -> -0.11695868
B15: Recommendation | C15: =IF(C13>0.1,"BUY",IF(C13<-0.1,"SELL","HOLD")) -> SELL
B16: Recommendation is based on total return approach (including dividends)
B19: Note : Given ITC’s diversified structure, a Sum-of-the-Parts (SOTP) approach may provide a more accurate valuation by valuing cigarettes, FMCG, and other segments separately. However, due to data constraints, a consolidated P/E-based valuation has been used.
