Workbook
Name UPDATE: 'Data Sheet'!#REF!

Sheet Data Sheet
A1: State Bank of India
A3: State Bank of India is a Fortune 500 company. It is an Indian Multinational, Public Sector banking and financial services statutory body headquartered in Mumbai. It is the largest and oldest bank in India with over 200 years of history
A7: Date : 29/04/2026
A8: META
A9: Number of shares | B9: =B12/B11 -> 923.31531 | C9: Cr
A10: Face Value | B10: 1
A11: Current Price | B11: 1091
A12: Market Capitalization | B12: 1007337 | C12: Cr
A13: 1 year high and Low | B13: 1234.70 /755.50
A14: Dividend Yearly | B14: May
A15: Dividend Yearly | B15: 15.9
A16: Dividend yield | B16: =B15/B11 -> 0.014573786
A18: PROFIT & LOSS (Consolidated figures in Cr)
A19: Report Date | B19: 44286 | C19: 44651 | D19: 45016 | E19: 45382 | F19: 45747
A20: Sales | B20: 278115.48 | C20: 289972.69 | D20: 350844.58 | E20: 439188.51 | F20: 490937.79
A21: Other Mfr. Exp | B21: 1116.5 | C21: 1219.04 | D21: 1305.59 | E21: 1448.83 | F21: 1553.6
A22: Employee Cost | B22: 54344.09 | C22: 61457.96 | D22: 61934.09 | E22: 83686.61 | F22: 70410.93
A23: Selling and admin | B23: 14050.25 | C23: 15354.12 | D23: 17241.04 | E23: 18170.92 | F23: 21639.1
A24: Other Expenses | B24: 123309.85 | C24: 119317.73 | D24: 123822.44 | E24: 136443.32 | F24: 158439.58
A25: Other Income | B25: 107222.41 | C25: 117000.4 | D25: 122533.56 | E25: 155386.39 | F25: 172405.53
A26: Depreciation | B26: 3711.06 | C26: 3691.27 | D26: 3695.6 | E26: 3849.12 | F26: 3991.48
A27: Interest | B27: 156010.17 | C27: 156194.34 | D27: 189980.82 | E27: 259736.05 | F27: 300943.34
A28: Profit before tax | B28: 32795.97 | C28: 49738.63 | D28: 75398.56 | E28: 91240.05 | F28: 106365.29
A29: Tax | B29: 8516.25 | C29: 13382.46 | D29: 18840.13 | E29: 23101.79 | F29: 27348.14
A30: Net profit | B30: 22405.46 | C30: 35373.88 | D30: 55648.17 | E30: 67084.67 | F30: 77561.34
A31: Dividend Amount | B31: 3569.84 | C31: 6336.47 | D31: 10084.8 | E31: 12226.7 | F31: 14190.11
A34: BALANCE SHEET
A35: Report Date | B35: 44286 | C35: 44651 | D35: 45016 | E35: 45382 | F35: 45747
A36: Equity Share Capital | B36: 892.46 | C36: 892.46 | D36: 892.46 | E36: 892.46 | F36: 892.46
A37: Reserves | B37: 274669.1 | C37: 304695.58 | D37: 358038.86 | E37: 414046.71 | F37: 486144.3
A38: Borrowings | B38: 4149127.5 | C38: 4536570.4 | D38: 4989687.5 | E38: 5606147 | F38: 6050755.3
A39: Other Liabilities | B39: 420925.83 | C39: 518719.42 | D39: 605795.73 | E39: 712669.43 | F39: 775937.87
A40: Total | B40: 4845614.8 | C40: 5360877.8 | D40: 5954414.5 | E40: 6733755.6 | F40: 7313729.9
A41: Net Block | B41: 41600.44 | C41: 41032.49 | D41: 45879.72 | E41: 46071.69 | F41: 47715.97
A42: Capital Work in Progress | B42: 116.35 | C42: 27.57 | D42: 66.02 | E42: 42.45 | F42: 41.4
A43: Investments | B43: 1595100.3 | C43: 1776489.9 | D43: 1913107.9 | E43: 2110548.2 | F43: 2205601.1
A44: Other Assets | B44: 3208797.8 | C44: 3543327.9 | D44: 3995360.9 | E44: 4577093.2 | F44: 5060371.4
A45: Total | B45: 4845614.8 | C45: 5360877.8 | D45: 5954414.5 | E45: 6733755.6 | F45: 7313729.9
A46: Receivables
A47: Inventory
...

Sheet Financial Statement
D5: EQUITY RESEARCH ON SBI
L6: By Aban Keot
C7: Actual | H7: Expected
B8: Report Date | C8: 44286 | D8: 44651 | E8: 45016 | F8: 45382 | G8: 45747 | H8: 46112 | I8: 46477 | J8: 46843 | K8: 47208 | L8: 47573
B9: Income Statement
B11: Total Operating Income | C11: ='Data Sheet'!B20+'Data Sheet'!B25 -> 385337.89 | D11: ='Data Sheet'!C20+'Data Sheet'!C25 -> 406973.09 | E11: ='Data Sheet'!D20+'Data Sheet'!D25 -> 473378.14 | F11: ='Data Sheet'!E20+'Data Sheet'!E25 -> 594574.9 | G11: ='Data Sheet'!F20+'Data Sheet'!F25 -> 663343.32 | H11: =G11*(1+H12) -> 749577.95 | I11: =H11*(1+I12) -> 847023.09 | J11: =I11*(1+J12) -> 957136.09 | K11: =J11*(1+K12) -> 1081563.8 | L11: =K11*(1+L12) -> 1222167.1
B12: Income Growth rate | D12: =D11/C11-1 -> 0.056146049 | E12: =E11/D11-1 -> 0.16316816 | F12: =F11/E11-1 -> 0.25602526 | G12: =G11/F11-1 -> 0.11565981 | H12: =Assumptions!$C$5 -> 0.13 | I12: =Assumptions!$C$5 -> 0.13 | J12: =Assumptions!$C$5 -> 0.13 | K12: =Assumptions!$C$5 -> 0.13 | L12: =Assumptions!$C$5 -> 0.13
A13: (oe=oi*Cir) | B13: Operating Expenses | C13: =SUM('Data Sheet'!B21:B24)+('Data Sheet'!B26) -> 196531.75 | D13: =SUM('Data Sheet'!C21:C24)+('Data Sheet'!C26) -> 201040.12 | E13: =SUM('Data Sheet'!D21:D24)+('Data Sheet'!D26) -> 207998.76 | F13: =SUM('Data Sheet'!E21:E24)+('Data Sheet'!E26) -> 243598.8 | G13: =SUM('Data Sheet'!F21:F24)+('Data Sheet'!F26) -> 256034.69 | H13: =H11*H14 -> 292335.4 | I13: =I11*I14 -> 330339 | J13: =J11*J14 -> 373283.07 | K13: =K11*K14 -> 421809.87 | L13: =L11*L14 -> 476645.16
B14: Cost to Income Ratio | C14: =C13/C11 -> 0.51002446 | D14: =D13/D11 -> 0.49398873 | E14: =E13/E11 -> 0.43939241 | F14: =F13/F11 -> 0.40970246 | G14: =G13/G11 -> 0.38597613 | H14: =Assumptions!$C$32 -> 0.39 | I14: =Assumptions!$C$32 -> 0.39 | J14: =Assumptions!$C$32 -> 0.39 | K14: =Assumptions!$C$32 -> 0.39 | L14: =Assumptions!$C$32 -> 0.39
B16: Operating Profit | C16: =C11-C13 -> 188806.14 | D16: =D11-D13 -> 205932.97 | E16: =E11-E13 -> 265379.38 | F16: =F11-F13 -> 350976.1 | G16: =G11-G13 -> 407308.63 | H16: =H11-H13 -> 457242.55 | I16: =I11-I13 -> 516684.08 | J16: =J11-J13 -> 583853.01 | ... L16: =L11-L13 -> 745521.91
B17: Operating Margin | C17: =C16/C11 -> 0.48997554 | D17: =D16/D11 -> 0.50601127 | E17: =E16/E11 -> 0.56060759 | F17: =F16/F11 -> 0.59029754 | G17: =G16/G11 -> 0.61402387 | H17: =H16/H11 -> 0.61 | I17: =I16/I11 -> 0.61 | J17: =J16/J11 -> 0.61 | ... L17: =L16/L11 -> 0.61
B19: Interest | C19: ='Data Sheet'!B27 -> 156010.17 | D19: ='Data Sheet'!C27 -> 156194.34 | E19: ='Data Sheet'!D27 -> 189980.82 | F19: ='Data Sheet'!E27 -> 259736.05 | G19: ='Data Sheet'!F27 -> 300943.34 | H19: =H11*H20 -> 311901.03 | I19: =I11*I20 -> 352448.16 | J19: =J11*J20 -> 398266.42 | K19: =K11*K20 -> 450041.06 | L19: =L11*L20 -> 508546.4
B20: Interest Rate (%) | C20: =C19/C11 -> 0.4048659 | D20: =D19/D11 -> 0.38379525 | E20: =E19/E11 -> 0.40132994 | F20: =F19/F11 -> 0.43684328 | G20: =G19/G11 -> 0.4536766 | H20: =Assumptions!$C$35 -> 0.41610219 | I20: =Assumptions!$C$35 -> 0.41610219 | J20: =Assumptions!$C$35 -> 0.41610219 | K20: =Assumptions!$C$35 -> 0.41610219 | L20: =Assumptions!$C$35 -> 0.41610219
B22: Profit Before Tax | C22: =C16-C19 -> 32795.97 | D22: =D16-D19 -> 49738.63 | E22: =E16-E19 -> 75398.56 | F22: =F16-F19 -> 91240.05 | G22: =G16-G19 -> 106365.29 | H22: =H16-H19 -> 145341.52 | I22: =I16-I19 -> 164235.92 | J22: =J16-J19 -> 185586.59 | ... L22: =L16-L19 -> 236975.51
B23: PBT % Income | C23: =C22/C11 -> 0.085109642 | D23: =D22/D11 -> 0.12221602 | E23: =E22/E11 -> 0.15927765 | F23: =F22/F11 -> 0.15345426 | G23: =G22/G11 -> 0.16034727 | H23: =H22/H11 -> 0.19389781 | I23: =I22/I11 -> 0.19389781 | J23: =J22/J11 -> 0.19389781 | ... L23: =L22/L11 -> 0.19389781
B25: Tax | C25: ='Data Sheet'!B29 -> 8516.25 | D25: ='Data Sheet'!C29 -> 13382.46 | E25: ='Data Sheet'!D29 -> 18840.13 | F25: ='Data Sheet'!E29 -> 23101.79 | G25: ='Data Sheet'!F29 -> 27348.14 | H25: =H22*H26 -> 37466.613 | I25: =I22*I26 -> 42337.273 | J25: =J22*J26 -> 47841.119 | K25: =K22*K26 -> 54060.464 | L25: =L22*L26 -> 61088.325
B26: Tax Rate % | C26: =C25/C22 -> 0.25967367 | D26: =D25/D22 -> 0.26905566 | E26: =E25/E22 -> 0.24987387 | F26: =F25/F22 -> 0.25319791 | G26: =G25/G22 -> 0.25711527 | H26: =Assumptions!$C$36 -> 0.25778328 | I26: =Assumptions!$C$36 -> 0.25778328 | J26: =Assumptions!$C$36 -> 0.25778328 | K26: =Assumptions!$C$36 -> 0.25778328 | L26: =Assumptions!$C$36 -> 0.25778328
B27: Net Profit | C27: =C22-C25 -> 24279.72 | D27: =D22-D25 -> 36356.17 | E27: =E22-E25 -> 56558.43 | F27: =F22-F25 -> 68138.26 | G27: =G22-G25 -> 79017.15 | H27: =G27*(1+Assumptions!$C$5) -> 89289.379 | I27: =H27*(1+Assumptions!$C$5) -> 100897 | J27: =I27*(1+Assumptions!$C$5) -> 114013.61 | K27: =J27*(1+Assumptions!$C$5) -> 128835.38 | L27: =K27*(1+Assumptions!$C$5) -> 145583.98
B29: Number of Shares | C29: ='Data Sheet'!B49 -> 8924611534 | D29: ='Data Sheet'!C49 -> 8924611534 | E29: ='Data Sheet'!D49 -> 8924611934 | F29: ='Data Sheet'!E49 -> 8924611934 | G29: ='Data Sheet'!F49 -> 8924620034 | H29: =Assumptions!$C$37 -> 8924620034 | I29: =Assumptions!$C$37 -> 8924620034 | J29: =Assumptions!$C$37 -> 8924620034 | K29: =Assumptions!$C$37 -> 8924620034 | L29: =Assumptions!$C$37 -> 8924620034
B30: Number of Shares in Cr | C30: =C29/10000000 -> 892.46115 | D30: =D29/10000000 -> 892.46115 | E30: =E29/10000000 -> 892.46119 | F30: =F29/10000000 -> 892.46119 | G30: =G29/10000000 -> 892.462 | H30: =Assumptions!$C$38 -> 892.462 | I30: =Assumptions!$C$38 -> 892.462 | J30: =Assumptions!$C$38 -> 892.462 | K30: =Assumptions!$C$38 -> 892.462 | L30: =Assumptions!$C$38 -> 892.462
B31: EPS | C31: =C27/C30 -> 27.205352 | D31: =D27/D30 -> 40.736978 | E31: =E27/E30 -> 63.373545 | F31: =F27/F30 -> 76.348709 | G31: =G27/G30 -> 88.538391 | H31: =H27/H30 -> 100.04838 | I31: =I27/I30 -> 113.05467 | J31: =J27/J30 -> 127.75178 | ... L31: =L27/L30 -> 163.12625

Sheet Assumptions
B4: REVENUE DRIVERS
B5: Loan Growth (%) | C5: 0.13 | D5: Based on SBI guidance and stable credit demand in the Indian banking sector.
B6: Bull Case | C6: 0.15
B7: Base Case | C7: 0.13
B8: Bear Case | C8: 0.11
B14: Net Interest Margin (%) | C14: 0.031 | D14: In line with historical trend, assuming stable interest rate environment.
B15: Other Income Growth (%) | C15: 0.1 | D15: Driven by growth in fee-based income and digital banking services.
B18: COST DRIVERS
B19: Operating Expense Growth (%) | C19: 0.09 | D19: Controlled cost growth due to increasing digitalization and operational efficiency.
A20: Efficiency | B20: Cost to Income Target (%) | C20: 0.4 | D20: Based on improving efficiency trend seen in past years.
B22: RISK DRIVERS
A23: Bad Loans | B23: GNPA(%) | C23: 0.016 | D23: Reflects continued improvement in asset quality from previous levels.
B24: Credit Cost (%) | C24: 0.01 | D24: Assumes stable provisioning requirement with better loan quality.
B27: VALUATION
B28: P/E Multiple | C28: 11x | D28: In line with typical valuation range of PSU banks in India.
B31: Cost to Income ratio is improving over year so we are taking 39% constant
B32: Cost to Income ratio | C32: 0.39
B34: Keeping Interest and Tax rate as Average
B35: Interest | C35: =AVERAGE('Financial Statement'!C20:G20) -> 0.41610219
B36: Tax | C36: =AVERAGE('Financial Statement'!C26:G26) -> 0.25778328
B37: Number of Share ( constant) | C37: ='Financial Statement'!G29 -> 8924620034
B38: Number of Share in Cr | C38: ='Financial Statement'!G30 -> 892.462

Sheet Valuation
B2: Choose Financial Year
B3: 47573 | C3: =_xlfn.XLOOKUP(B3,'Financial Statement'!H8:L8,'Financial Statement'!H31:L31,"",0) -> 163.12625
B5: EPS Forward | C5: =C3 -> 163.12625
B7: Target P/E | C7: 11 | D7: Typical range for PSU banks
B9: Target Price | C9: =C7*C5 -> 1794.3887
B11: Current Price | C11: ='Data Sheet'!B11 -> 1091
B13: Dividend Yield | C13: ='Data Sheet'!B16 -> 0.014573786
B15: Price Return | C15: =(C9/C11)-1 -> 0.64471926
B17: Total Expected Return | C17: =C15+C13 -> 0.65929305
B19: Recommendation | C19: =IF(C17>0.1,"BUY",IF(C17<-0.1,"SELL","HOLD")) -> BUY
